Workbook

Sheet 説明
A1: 篠原組『あの日僕は、名前のない違和感を感じた』撮影スケジュール検証モデル（2026-10-18 作成）
A3: ■ 使い方
A4: ・青字＝入力値（変えてOK）。黒字＝計算式。黄色セル＝根拠が弱いので、ロケハンや監督確認で上書きしたい値。
A5: ・『係数』シートの値を変えると、シーン見積 → 日別 → 感度分析 がすべて再計算されます。
A6: ・『シーン見積』の『感度倍率』列（初期値1.0）を変えると、そのシーンだけ見積もりを伸び縮みさせられます。
A8: ■ 見積もりの式（1シーンあたり）
A9: 所要時間 ＝ 準備 ＋ 撮影 ＋ 切り替え
A10: 準備 ＝ 準備種別ごとの値（屋内新規／屋外新規／同一継続）
A11: 撮影 ＝ 構図数 ×（リハ・段取り ＋ テイク数 × 1テイクの長さ）＋ 長回し構図数 × 長回し追加係数 × テイク数 × 1テイクの長さ
A12: テイク数 ＝ 基本テイク数 × 子役係数 × 動物係数 × エキストラ係数 × アクション成功係数
A13: 1テイクの長さ ＝ 平均尺(秒)/60 ＋ リセット ＋（大リセットありなら 大リセット追加）
A14: 切り替え ＝（構図数−1）× 構図切替 ＋ 未確定構図数 × 現場検証時間
... A24: ・引き継ぎ資料（.md）は今回添付されていなかったため、資料の『0』『7』『※』の数字は確認できていません。『要確認』シートを参照してください。

Sheet 係数
A1: 係数（シナリオ別）
A3: 項目 | B3: 最短 | C3: 標準 | D3: 余裕 | E3: 根拠・メモ
A4: 基本テイク数（回/構図） | B4: 2 | C4: 3 | D4: 3.5 | E4: 自主制作・子役中心の一般的な目安。最短は「2回でOK」想定
A5: リハ・段取り（分/構図） | B5: 1 | C5: 1.5 | D5: 2 | E5: 立ち位置確認・カメラリハ
A6: リセット（分/テイク） | B6: 0.5 | C6: 0.8 | D6: 1.2 | E6: 位置戻し・スレート
A7: 大リセット追加（分/テイク） | B7: 1.5 | C7: 2.5 | D7: 4 | E7: エキストラ全員を教室へ戻す／砂浜の足跡を消す等
A8: 構図切替（分/回） | B8: 4 | C8: 6 | D8: 8 | E8: カメラ位置・照明の微調整
A9: 未確定構図の現場検証（分/構図） | B9: 2 | C9: 4 | D9: 6 | E9: ピンク・赤マーカー＝現場で検証
A10: 屋内新規 | B10: 12 | C10: 20 | D10: 30 | E10: 準備：屋内・新しい場所（照明設営）
A11: 屋外新規 | B11: 8 | C11: 12 | D11: 18 | E11: 準備：屋外・新しい場所
A12: 同一継続 | B12: 3 | C12: 5 | D12: 8 | E12: 準備：同じ場所の続き
A13: 長回し追加係数 | B13: 0.5 | C13: 0.5 | D13: 0.5 | E13: 長回し・ワンカット・「最低20秒」の構図はテイク時間を×(1+係数)
A14: ピンマイク作業（分/人） | B14: 2 | C14: 3 | D14: 5 | E14: 昼食後の再確認・途中入りの装着
A17: 係数（シナリオ共通）
A18: 子役人数（芝居をする子） | B18: 係数 | E18: メモ
A19: 0 | B19: 1
A20: 1 | B20: 1.1
A21: 2 | B21: 1.2
A22: 3 | B22: 1.3 | E22: 3人以上は1.3
A24: エキストラ人数（下限） | B24: 係数 | E24: メモ
A25: 0 | B25: 1 | E25: 0人
A26: 1 | B26: 1.1 | E26: 1〜5人
A27: 6 | B27: 1.25 | E27: 6〜15人
A28: 16 | B28: 1.4 | E28: 16人以上
A30: その他 | B30: 係数 | E30: メモ
A31: 動物係数 | B31: 1.5 | E31: S2 パンチ（犬）
A32: アクション成功係数 | B32: 1.3 | E32: シュートを決める等、成功するまで撮る動き（S15）
A34: 児童の実働の目安（分/日） | B34: 420 | E34: 労働基準法の年少者規定（児童：1日7時間）を目安として使用。適用の有無は要確認

Sheet シーン見積
A1: シーンごとの見積もり（分）
A2: 青字＝入力。黄色＝根拠が弱い値（構図マーカーなし・エキストラ人数未確定）。
A3: S | B3: 日付 | C3: ブロック | D3: 場所（脚本） | E3: 屋内外 | F3: 時間帯（脚本） | G3: 現行の枠(分) | H3: 構図数 | I3: セリフ行数 | J3: 子役人数(芝居) | K3: 大人キャスト | L3: 動物 | M3: エキストラ人数 | N3: 長回し構図数 | O3: 未確定構図数 | P3: アクション成功 | Q3: 大リセット | R3: 準備種別 | S3: 平均尺(秒) | T3: 小道具 | U3: 動き・指定（脚本より） | V3: テイク係数 | W3: 最短:準備 | X3: 最短:撮影 | Y3: 最短:切替 | Z3: 最短:合計 | AA3: 標準:準備 | AB3: 標準:撮影 | AC3: 標準:切替 | AD3: 標準:合計 | AE3: 余裕:準備 | AF3: 余裕:撮影 | AG3: 余裕:切替 | AH3: 余裕:合計 | AI3: 感度倍率 | AJ3: 判定 | AK3: 枠−標準 | AL3: 現行の開始 | AM3: 現行の終了
A4: 3 | B4: 46326 | C4: D1 | D4: 小学校・校門 | E4: 屋外 | F4: 朝 | G4: 30 | H4: 3 | I4: 5 | J4: 2 | K4: 1 | L4: 0 | M4: 10 | N4: 2 | O4: 0 | P4: 0 | Q4: 0 | R4: 屋外新規 | S4: 20 | T4: ランドセル・脚立 | U4: 脚立で高い位置から／広角で追う（A）／後ろ姿を追う（C） | V4: =VLOOKUP(MIN(J4,3),係数!$A$19:$B$22,2,TRUE())*IF(L4=1,係数!$B$31,1)*VLOOKUP(M4,係数!$A$25:$B$28,2,TRUE())*IF(P4=1,係数!$B$32,1) -> 1.5 | W4: =INDEX(係数!$B$10:$B$12,MATCH(R4,係数!$A$10:$A$12,0)) -> 8 | X4: =H4*(係数!$B$5+係数!$B$4*V4*(S4/60+係数!$B$6+Q4*係数!$B$7))+N4*係数!$B$13*係数!$B$4*V4*(S4/60+係数!$B$6+Q4*係数!$B$7) -> 13 | Y4: =MAX(H4-1,0)*係数!$B$8+O4*係数!$B$9 -> 8 | Z4: =ROUND((W4+X4+Y4)*AI4,0) -> 29 | AA4: =INDEX(係数!$C$10:$C$12,MATCH(R4,係数!$A$10:$A$12,0)) -> 12 | AB4: =H4*(係数!$C$5+係数!$C$4*V4*(S4/60+係数!$C$6+Q4*係数!$C$7))+N4*係数!$C$13*係数!$C$4*V4*(S4/60+係数!$C$6+Q4*係数!$C$7) -> 24.9 | AC4: =MAX(H4-1,0)*係数!$C$8+O4*係数!$C$9 -> 12 | AD4: =ROUND((AA4+AB4+AC4)*AI4,0) -> 49 | AE4: =INDEX(係数!$D$10:$D$12,MATCH(R4,係数!$A$10:$A$12,0)) -> 18 | AF4: =H4*(係数!$D$5+係数!$D$4*V4*(S4/60+係数!$D$6+Q4*係数!$D$7))+N4*係数!$D$13*係数!$D$4*V4*(S4/60+係数!$D$6+Q4*係数!$D$7) -> 38.2 | AG4: =MAX(H4-1,0)*係数!$D$8+O4*係数!$D$9 -> 16 | AH4: =ROUND((AE4+AF4+AG4)*AI4,0) -> 72 | AI4: 1 | AJ4: =IF(G4>=AH4,"余裕あり",IF(G4>=AD4,"適正",IF(G4>=Z4,"ギリギリ","不足"))) -> ギリギリ | AK4: =G4-AD4 -> -19 | AL4: 0.47916667 | AM4: 0.5
A5: 4 | B5: 46326 | C5: D1 | D5: 同・階段 | E5: 屋内 | F5: 朝 | G5: 40 | H5: 1 | I5: 1 | J5: 2 | K5: 0 | L5: 0 | M5: 10 | N5: 1 | O5: 0 | P5: 0 | Q5: 1 | R5: 屋内新規 | S5: 40 | T5: ランドセル | U5: ワンカット：手を振り合って別れるまで、カメラが階段を一緒に登る | V5: =VLOOKUP(MIN(J5,3),係数!$A$19:$B$22,2,TRUE())*IF(L5=1,係数!$B$31,1)*VLOOKUP(M5,係数!$A$25:$B$28,2,TRUE())*IF(P5=1,係数!$B$32,1) -> 1.5 | W5: =INDEX(係数!$B$10:$B$12,MATCH(R5,係数!$A$10:$A$12,0)) -> 12 | X5: =H5*(係数!$B$5+係数!$B$4*V5*(S5/60+係数!$B$6+Q5*係数!$B$7))+N5*係数!$B$13*係数!$B$4*V5*(S5/60+係数!$B$6+Q5*係数!$B$7) -> 13 | Y5: =MAX(H5-1,0)*係数!$B$8+O5*係数!$B$9 -> 0 | Z5: =ROUND((W5+X5+Y5)*AI5,0) -> 25 | AA5: =INDEX(係数!$C$10:$C$12,MATCH(R5,係数!$A$10:$A$12,0)) -> 20 | AB5: =H5*(係数!$C$5+係数!$C$4*V5*(S5/60+係数!$C$6+Q5*係数!$C$7))+N5*係数!$C$13*係数!$C$4*V5*(S5/60+係数!$C$6+Q5*係数!$C$7) -> 28.275 | AC5: =MAX(H5-1,0)*係数!$C$8+O5*係数!$C$9 -> 0 | AD5: =ROUND((AA5+AB5+AC5)*AI5,0) -> 48 | AE5: =INDEX(係数!$D$10:$D$12,MATCH(R5,係数!$A$10:$A$12,0)) -> 30 | AF5: =H5*(係数!$D$5+係数!$D$4*V5*(S5/60+係数!$D$6+Q5*係数!$D$7))+N5*係数!$D$13*係数!$D$4*V5*(S5/60+係数!$D$6+Q5*係数!$D$7) -> 48.2 | AG5: =MAX(H5-1,0)*係数!$D$8+O5*係数!$D$9 -> 0 | AH5: =ROUND((AE5+AF5+AG5)*AI5,0) -> 78 | AI5: 1 | AJ5: =IF(G5>=AH5,"余裕あり",IF(G5>=AD5,"適正",IF(G5>=Z5,"ギリギリ","不足"))) -> ギリギリ | AK5: =G5-AD5 -> -8 | AL5: 0.50694444 | AM5: 0.53472222
A6: 16A | B6: 46326 | C6: D1 | D6: 同・校庭（エキストラ別撮り） | E6: 屋外 | F6: 昼過ぎ | G6: 40 | H6: 1 | I6: 0 | J6: 0 | K6: 0 | L6: 0 | M6: 10 | N6: 0 | O6: 0 | P6: 0 | Q6: 0 | R6: 屋外新規 | S6: 20 | T6: サッカーボール・ペットボトル | U6: エキストラのみ。サッカー／ペットボトルを狙うゲーム | V6: =VLOOKUP(MIN(J6,3),係数!$A$19:$B$22,2,TRUE())*IF(L6=1,係数!$B$31,1)*VLOOKUP(M6,係数!$A$25:$B$28,2,TRUE())*IF(P6=1,係数!$B$32,1) -> 1.25 | W6: =INDEX(係数!$B$10:$B$12,MATCH(R6,係数!$A$10:$A$12,0)) -> 8 | X6: =H6*(係数!$B$5+係数!$B$4*V6*(S6/60+係数!$B$6+Q6*係数!$B$7))+N6*係数!$B$13*係数!$B$4*V6*(S6/60+係数!$B$6+Q6*係数!$B$7) -> 3.0833333 | Y6: =MAX(H6-1,0)*係数!$B$8+O6*係数!$B$9 -> 0 | Z6: =ROUND((W6+X6+Y6)*AI6,0) -> 11 | AA6: =INDEX(係数!$C$10:$C$12,MATCH(R6,係数!$A$10:$A$12,0)) -> 12 | AB6: =H6*(係数!$C$5+係数!$C$4*V6*(S6/60+係数!$C$6+Q6*係数!$C$7))+N6*係数!$C$13*係数!$C$4*V6*(S6/60+係数!$C$6+Q6*係数!$C$7) -> 5.75 | AC6: =MAX(H6-1,0)*係数!$C$8+O6*係数!$C$9 -> 0 | AD6: =ROUND((AA6+AB6+AC6)*AI6,0) -> 18 | AE6: =INDEX(係数!$D$10:$D$12,MATCH(R6,係数!$A$10:$A$12,0)) -> 18 | AF6: =H6*(係数!$D$5+係数!$D$4*V6*(S6/60+係数!$D$6+Q6*係数!$D$7))+N6*係数!$D$13*係数!$D$4*V6*(S6/60+係数!$D$6+Q6*係数!$D$7) -> 8.7083333 | AG6: =MAX(H6-1,0)*係数!$D$8+O6*係数!$D$9 -> 0 | AH6: =ROUND((AE6+AF6+AG6)*AI6,0) -> 27 | AI6: 1 | AJ6: =IF(G6>=AH6,"余裕あり",IF(G6>=AD6,"適正",IF(G6>=Z6,"ギリギリ","不足"))) -> 余裕あり | AK6: =G6-AD6 -> 22 | AL6: 0.56944444 | AM6: 0.59722222
A7: 13 | B7: 46326 | C7: D1 | D7: 同・校庭 | E7: 屋外 | F7: （指定なし） | G7: 90 | H7: 3 | I7: 6 | J7: 1 | K7: 0 | L7: 0 | M7: 3 | N7: 1 | O7: 0 | P7: 0 | Q7: 0 | R7: 同一継続 | S7: 20 | U7: 男子3人は当日エキストラから選ぶ／足元からソウタの顔まで上がる（C） | V7: =VLOOKUP(MIN(J7,3),係数!$A$19:$B$22,2,TRUE())*IF(L7=1,係数!$B$31,1)*VLOOKUP(M7,係数!$A$25:$B$28,2,TRUE())*IF(P7=1,係数!$B$32,1) -> 1.21 | W7: =INDEX(係数!$B$10:$B$12,MATCH(R7,係数!$A$10:$A$12,0)) -> 3 | X7: =H7*(係数!$B$5+係数!$B$4*V7*(S7/60+係数!$B$6+Q7*係数!$B$7))+N7*係数!$B$13*係数!$B$4*V7*(S7/60+係数!$B$6+Q7*係数!$B$7) -> 10.058333 | Y7: =MAX(H7-1,0)*係数!$B$8+O7*係数!$B$9 -> 8 | Z7: =ROUND((W7+X7+Y7)*AI7,0) -> 21 | AA7: =INDEX(係数!$C$10:$C$12,MATCH(R7,係数!$A$10:$A$12,0)) -> 5 | AB7: =H7*(係数!$C$5+係数!$C$4*V7*(S7/60+係数!$C$6+Q7*係数!$C$7))+N7*係数!$C$13*係数!$C$4*V7*(S7/60+係数!$C$6+Q7*係数!$C$7) -> 18.899 | AC7: =MAX(H7-1,0)*係数!$C$8+O7*係数!$C$9 -> 12 | AD7: =ROUND((AA7+AB7+AC7)*AI7,0) -> 36 | AE7: =INDEX(係数!$D$10:$D$12,MATCH(R7,係数!$A$10:$A$12,0)) -> 8 | AF7: =H7*(係数!$D$5+係数!$D$4*V7*(S7/60+係数!$D$6+Q7*係数!$D$7))+N7*係数!$D$13*係数!$D$4*V7*(S7/60+係数!$D$6+Q7*係数!$D$7) -> 28.727833 | AG7: =MAX(H7-1,0)*係数!$D$8+O7*係数!$D$9 -> 16 | AH7: =ROUND((AE7+AF7+AG7)*AI7,0) -> 53 | AI7: 1 | AJ7: =IF(G7>=AH7,"余裕あり",IF(G7>=AD7,"適正",IF(G7>=Z7,"ギリギリ","不足"))) -> 余裕あり | AK7: =G7-AD7 -> 54 | AL7: 0.60416667 | AM7: 0.66666667
A8: 5 | B8: 46327 | C8: D2a | D8: 同・教室（朝の会） | E8: 屋内 | F8: 朝 | G8: 80 | H8: 10 | I8: 9 | J8: 2 | K8: 1 | L8: 0 | M8: 12 | N8: 2 | O8: 0 | P8: 0 | Q8: 0 | R8: 屋内新規 | S8: 20 | T8: 出席簿・チョーク・椅子 | U8: 12名ほど。B：席まで歩く／C：座るまで同構図／J：机の下からカメラが上がる。「間」が超重要 | V8: =VLOOKUP(MIN(J8,3),係数!$A$19:$B$22,2,TRUE())*IF(L8=1,係数!$B$31,1)*VLOOKUP(M8,係数!$A$25:$B$28,2,TRUE())*IF(P8=1,係数!$B$32,1) -> 1.5 | W8: =INDEX(係数!$B$10:$B$12,MATCH(R8,係数!$A$10:$A$12,0)) -> 12 | X8: =H8*(係数!$B$5+係数!$B$4*V8*(S8/60+係数!$B$6+Q8*係数!$B$7))+N8*係数!$B$13*係数!$B$4*V8*(S8/60+係数!$B$6+Q8*係数!$B$7) -> 37.5 | Y8: =MAX(H8-1,0)*係数!$B$8+O8*係数!$B$9 -> 36 | Z8: =ROUND((W8+X8+Y8)*AI8,0) -> 86 | AA8: =INDEX(係数!$C$10:$C$12,MATCH(R8,係数!$A$10:$A$12,0)) -> 20 | AB8: =H8*(係数!$C$5+係数!$C$4*V8*(S8/60+係数!$C$6+Q8*係数!$C$7))+N8*係数!$C$13*係数!$C$4*V8*(S8/60+係数!$C$6+Q8*係数!$C$7) -> 71.1 | AC8: =MAX(H8-1,0)*係数!$C$8+O8*係数!$C$9 -> 54 | AD8: =ROUND((AA8+AB8+AC8)*AI8,0) -> 145 | AE8: =INDEX(係数!$D$10:$D$12,MATCH(R8,係数!$A$10:$A$12,0)) -> 30 | AF8: =H8*(係数!$D$5+係数!$D$4*V8*(S8/60+係数!$D$6+Q8*係数!$D$7))+N8*係数!$D$13*係数!$D$4*V8*(S8/60+係数!$D$6+Q8*係数!$D$7) -> 108.55 | AG8: =MAX(H8-1,0)*係数!$D$8+O8*係数!$D$9 -> 72 | AH8: =ROUND((AE8+AF8+AG8)*AI8,0) -> 211 | AI8: 1 | AJ8: =IF(G8>=AH8,"余裕あり",IF(G8>=AD8,"適正",IF(G8>=Z8,"ギリギリ","不足"))) -> 不足 | AK8: =G8-AD8 -> -65 | AL8: 0.4375 | AM8: 0.49305556
A9: 6 | B9: 46327 | C9: D2a | D9: 同・教室（国語） | E9: 屋内 | F9: （授業中） | G9: 30 | H9: 2 | I9: 0 | J9: 1 | K9: 1 | L9: 0 | M9: 12 | N9: 0 | O9: 0 | P9: 0 | Q9: 0 | R9: 同一継続 | S9: 30 | T9: 教科書・消しゴム・時計 | U9: 時計の時間変更。生徒それぞれの芝居（誰が何をするかは未定） | V9: =VLOOKUP(MIN(J9,3),係数!$A$19:$B$22,2,TRUE())*IF(L9=1,係数!$B$31,1)*VLOOKUP(M9,係数!$A$25:$B$28,2,TRUE())*IF(P9=1,係数!$B$32,1) -> 1.375 | W9: =INDEX(係数!$B$10:$B$12,MATCH(R9,係数!$A$10:$A$12,0)) -> 3 | X9: =H9*(係数!$B$5+係数!$B$4*V9*(S9/60+係数!$B$6+Q9*係数!$B$7))+N9*係数!$B$13*係数!$B$4*V9*(S9/60+係数!$B$6+Q9*係数!$B$7) -> 7.5 | Y9: =MAX(H9-1,0)*係数!$B$8+O9*係数!$B$9 -> 4 | Z9: =ROUND((W9+X9+Y9)*AI9,0) -> 15 | AA9: =INDEX(係数!$C$10:$C$12,MATCH(R9,係数!$A$10:$A$12,0)) -> 5 | AB9: =H9*(係数!$C$5+係数!$C$4*V9*(S9/60+係数!$C$6+Q9*係数!$C$7))+N9*係数!$C$13*係数!$C$4*V9*(S9/60+係数!$C$6+Q9*係数!$C$7) -> 13.725 | AC9: =MAX(H9-1,0)*係数!$C$8+O9*係数!$C$9 -> 6 | AD9: =ROUND((AA9+AB9+AC9)*AI9,0) -> 25 | AE9: =INDEX(係数!$D$10:$D$12,MATCH(R9,係数!$A$10:$A$12,0)) -> 8 | AF9: =H9*(係数!$D$5+係数!$D$4*V9*(S9/60+係数!$D$6+Q9*係数!$D$7))+N9*係数!$D$13*係数!$D$4*V9*(S9/60+係数!$D$6+Q9*係数!$D$7) -> 20.3625 | AG9: =MAX(H9-1,0)*係数!$D$8+O9*係数!$D$9 -> 8 | AH9: =ROUND((AE9+AF9+AG9)*AI9,0) -> 36 | AI9: 1 | AJ9: =IF(G9>=AH9,"余裕あり",IF(G9>=AD9,"適正",IF(G9>=Z9,"ギリギリ","不足"))) -> 適正 | AK9: =G9-AD9 -> 5 | AL9: 0.5 | AM9: 0.52083333
A10: 8 | B10: 46327 | C10: D2a | D10: 同・教室（ソワソワ） | E10: 屋内 | F10: 10:18 | G10: 25 | H10: 2 | I10: 0 | J10: 0 | K10: 0 | L10: 0 | M10: 12 | N10: 0 | O10: 0 | P10: 0 | Q10: 0 | R10: 同一継続 | S10: 15 | T10: 時計(10:18)・ボール・ボールネット | U10: 時計の寄り／ボールを追う | V10: =VLOOKUP(MIN(J10,3),係数!$A$19:$B$22,2,TRUE())*IF(L10=1,係数!$B$31,1)*VLOOKUP(M10,係数!$A$25:$B$28,2,TRUE())*IF(P10=1,係数!$B$32,1) -> 1.25 | W10: =INDEX(係数!$B$10:$B$12,MATCH(R10,係数!$A$10:$A$12,0)) -> 3 | X10: =H10*(係数!$B$5+係数!$B$4*V10*(S10/60+係数!$B$6+Q10*係数!$B$7))+N10*係数!$B$13*係数!$B$4*V10*(S10/60+係数!$B$6+Q10*係数!$B$7) -> 5.75 | Y10: =MAX(H10-1,0)*係数!$B$8+O10*係数!$B$9 -> 4 | Z10: =ROUND((W10+X10+Y10)*AI10,0) -> 13 | AA10: =INDEX(係数!$C$10:$C$12,MATCH(R10,係数!$A$10:$A$12,0)) -> 5 | AB10: =H10*(係数!$C$5+係数!$C$4*V10*(S10/60+係数!$C$6+Q10*係数!$C$7))+N10*係数!$C$13*係数!$C$4*V10*(S10/60+係数!$C$6+Q10*係数!$C$7) -> 10.875 | AC10: =MAX(H10-1,0)*係数!$C$8+O10*係数!$C$9 -> 6 | AD10: =ROUND((AA10+AB10+AC10)*AI10,0) -> 22 | AE10: =INDEX(係数!$D$10:$D$12,MATCH(R10,係数!$A$10:$A$12,0)) -> 8 | AF10: =H10*(係数!$D$5+係数!$D$4*V10*(S10/60+係数!$D$6+Q10*係数!$D$7))+N10*係数!$D$13*係数!$D$4*V10*(S10/60+係数!$D$6+Q10*係数!$D$7) -> 16.6875 | AG10: =MAX(H10-1,0)*係数!$D$8+O10*係数!$D$9 -> 8 | AH10: =ROUND((AE10+AF10+AG10)*AI10,0) -> 33 | AI10: 1 | AJ10: =IF(G10>=AH10,"余裕あり",IF(G10>=AD10,"適正",IF(G10>=Z10,"ギリギリ","不足"))) -> 適正 | AK10: =G10-AD10 -> 3 | AL10: 0.5625 | AM10: 0.57986111
A11: 9 | B11: 46327 | C11: D2a | D11: 同・廊下 | E11: 屋内 | F11: 10:20 | G11: 20 | H11: 1 | I11: 2 | J11: 0 | K11: 1 | L11: 0 | M11: 12 | N11: 1 | O11: 0 | P11: 0 | Q11: 1 | R11: 屋内新規 | S11: 20 | T11: 段ボール・ボール | U11: 全員が教室を飛び出す（望遠）。本番前に熱を作る。テイクごとに全員を戻す | V11: =VLOOKUP(MIN(J11,3),係数!$A$19:$B$22,2,TRUE())*IF(L11=1,係数!$B$31,1)*VLOOKUP(M11,係数!$A$25:$B$28,2,TRUE())*IF(P11=1,係数!$B$32,1) -> 1.25 | W11: =INDEX(係数!$B$10:$B$12,MATCH(R11,係数!$A$10:$A$12,0)) -> 12 | X11: =H11*(係数!$B$5+係数!$B$4*V11*(S11/60+係数!$B$6+Q11*係数!$B$7))+N11*係数!$B$13*係数!$B$4*V11*(S11/60+係数!$B$6+Q11*係数!$B$7) -> 9.75 | Y11: =MAX(H11-1,0)*係数!$B$8+O11*係数!$B$9 -> 0 | Z11: =ROUND((W11+X11+Y11)*AI11,0) -> 22 | AA11: =INDEX(係数!$C$10:$C$12,MATCH(R11,係数!$A$10:$A$12,0)) -> 20 | AB11: =H11*(係数!$C$5+係数!$C$4*V11*(S11/60+係数!$C$6+Q11*係数!$C$7))+N11*係数!$C$13*係数!$C$4*V11*(S11/60+係数!$C$6+Q11*係数!$C$7) -> 21.9375 | AC11: =MAX(H11-1,0)*係数!$C$8+O11*係数!$C$9 -> 0 | AD11: =ROUND((AA11+AB11+AC11)*AI11,0) -> 42 | AE11: =INDEX(係数!$D$10:$D$12,MATCH(R11,係数!$A$10:$A$12,0)) -> 30 | AF11: =H11*(係数!$D$5+係数!$D$4*V11*(S11/60+係数!$D$6+Q11*係数!$D$7))+N11*係数!$D$13*係数!$D$4*V11*(S11/60+係数!$D$6+Q11*係数!$D$7) -> 38.3125 | AG11: =MAX(H11-1,0)*係数!$D$8+O11*係数!$D$9 -> 0 | AH11: =ROUND((AE11+AF11+AG11)*AI11,0) -> 68 | AI11: 1 | AJ11: =IF(G11>=AH11,"余裕あり",IF(G11>=AD11,"適正",IF(G11>=Z11,"ギリギリ","不足"))) -> 不足 | AK11: =G11-AD11 -> -22 | AL11: 0.57986111 | AM11: 0.59375
A12: 10 | B12: 46327 | C12: D2a | D12: 同・教室（はい） | E12: 屋内 | F12: 中休み | G12: 30 | H12: 2 | I12: 2 | J12: 1 | K12: 1 | L12: 0 | M12: 3 | N12: 1 | O12: 0 | P12: 0 | Q12: 0 | R12: 同一継続 | S12: 30 | T12: ノート・ペン・散らかった教科書 | U12: 女子2〜3人。B：野口が歩いてきてカメラも寄る | V12: =VLOOKUP(MIN(J12,3),係数!$A$19:$B$22,2,TRUE())*IF(L12=1,係数!$B$31,1)*VLOOKUP(M12,係数!$A$25:$B$28,2,TRUE())*IF(P12=1,係数!$B$32,1) -> 1.21 | W12: =INDEX(係数!$B$10:$B$12,MATCH(R12,係数!$A$10:$A$12,0)) -> 3 | X12: =H12*(係数!$B$5+係数!$B$4*V12*(S12/60+係数!$B$6+Q12*係数!$B$7))+N12*係数!$B$13*係数!$B$4*V12*(S12/60+係数!$B$6+Q12*係数!$B$7) -> 8.05 | Y12: =MAX(H12-1,0)*係数!$B$8+O12*係数!$B$9 -> 4 | Z12: =ROUND((W12+X12+Y12)*AI12,0) -> 15 | AA12: =INDEX(係数!$C$10:$C$12,MATCH(R12,係数!$A$10:$A$12,0)) -> 5 | AB12: =H12*(係数!$C$5+係数!$C$4*V12*(S12/60+係数!$C$6+Q12*係数!$C$7))+N12*係数!$C$13*係数!$C$4*V12*(S12/60+係数!$C$6+Q12*係数!$C$7) -> 14.7975 | AC12: =MAX(H12-1,0)*係数!$C$8+O12*係数!$C$9 -> 6 | AD12: =ROUND((AA12+AB12+AC12)*AI12,0) -> 26 | AE12: =INDEX(係数!$D$10:$D$12,MATCH(R12,係数!$A$10:$A$12,0)) -> 8 | AF12: =H12*(係数!$D$5+係数!$D$4*V12*(S12/60+係数!$D$6+Q12*係数!$D$7))+N12*係数!$D$13*係数!$D$4*V12*(S12/60+係数!$D$6+Q12*係数!$D$7) -> 21.99875 | AG12: =MAX(H12-1,0)*係数!$D$8+O12*係数!$D$9 -> 8 | AH12: =ROUND((AE12+AF12+AG12)*AI12,0) -> 38 | AI12: 1 | AJ12: =IF(G12>=AH12,"余裕あり",IF(G12>=AD12,"適正",IF(G12>=Z12,"ギリギリ","不足"))) -> 適正 | AK12: =G12-AD12 -> 4 | AL12: 0.59375 | AM12: 0.61458333
A13: 18 | B13: 46327 | C13: D2b | D13: 同・教室（帰りの会） | E13: 屋内 | F13: 放課後 | G13: 75 | H13: 5 | I13: 8 | J13: 2 | K13: 1 | L13: 0 | M13: 12 | N13: 2 | O13: 0 | P13: 0 | Q13: 0 | R13: 同一継続 | S13: 25 | T13: プリント・クリアファイル・ランドセル・黒板消し | U13: A：黒板消しの寄りから引いてパン／E：左に動く | V13: =VLOOKUP(MIN(J13,3),係数!$A$19:$B$22,2,TRUE())*IF(L13=1,係数!$B$31,1)*VLOOKUP(M13,係数!$A$25:$B$28,2,TRUE())*IF(P13=1,係数!$B$32,1) -> 1.5 | W13: =INDEX(係数!$B$10:$B$12,MATCH(R13,係数!$A$10:$A$12,0)) -> 3 | X13: =H13*(係数!$B$5+係数!$B$4*V13*(S13/60+係数!$B$6+Q13*係数!$B$7))+N13*係数!$B$13*係数!$B$4*V13*(S13/60+係数!$B$6+Q13*係数!$B$7) -> 21.5 | Y13: =MAX(H13-1,0)*係数!$B$8+O13*係数!$B$9 -> 16 | Z13: =ROUND((W13+X13+Y13)*AI13,0) -> 41 | AA13: =INDEX(係数!$C$10:$C$12,MATCH(R13,係数!$A$10:$A$12,0)) -> 5 | AB13: =H13*(係数!$C$5+係数!$C$4*V13*(S13/60+係数!$C$6+Q13*係数!$C$7))+N13*係数!$C$13*係数!$C$4*V13*(S13/60+係数!$C$6+Q13*係数!$C$7) -> 40.35 | AC13: =MAX(H13-1,0)*係数!$C$8+O13*係数!$C$9 -> 24 | AD13: =ROUND((AA13+AB13+AC13)*AI13,0) -> 69 | AE13: =INDEX(係数!$D$10:$D$12,MATCH(R13,係数!$A$10:$A$12,0)) -> 8 | AF13: =H13*(係数!$D$5+係数!$D$4*V13*(S13/60+係数!$D$6+Q13*係数!$D$7))+N13*係数!$D$13*係数!$D$4*V13*(S13/60+係数!$D$6+Q13*係数!$D$7) -> 60.925 | AG13: =MAX(H13-1,0)*係数!$D$8+O13*係数!$D$9 -> 32 | AH13: =ROUND((AE13+AF13+AG13)*AI13,0) -> 101 | AI13: 1 | AJ13: =IF(G13>=AH13,"余裕あり",IF(G13>=AD13,"適正",IF(G13>=Z13,"ギリギリ","不足"))) -> 適正 | AK13: =G13-AD13 -> 6 | AL13: 0.63541667 | AM13: 0.6875
A14: 15 | B14: 46329 | C14: D3a | D14: 同・体育館 | E14: 屋内 | F14: （休み時間） | G14: 120 | H14: 12 | I14: 17 | J14: 3 | K14: 1 | L14: 0 | M14: 0 | N14: 3 | O14: 12 | P14: 1 | Q14: 0 | R14: 屋内新規 | S14: 25 | T14: 本（5冊・3冊）・バスケットボール | U14: 構図A〜Lすべて未確定。シュート（F・G）、天井通路から広角（G）、J：同構図で20秒 | V14: =VLOOKUP(MIN(J14,3),係数!$A$19:$B$22,2,TRUE())*IF(L14=1,係数!$B$31,1)*VLOOKUP(M14,係数!$A$25:$B$28,2,TRUE())*IF(P14=1,係数!$B$32,1) -> 1.69 | W14: =INDEX(係数!$B$10:$B$12,MATCH(R14,係数!$A$10:$A$12,0)) -> 12 | X14: =H14*(係数!$B$5+係数!$B$4*V14*(S14/60+係数!$B$6+Q14*係数!$B$7))+N14*係数!$B$13*係数!$B$4*V14*(S14/60+係数!$B$6+Q14*係数!$B$7) -> 53.8275 | Y14: =MAX(H14-1,0)*係数!$B$8+O14*係数!$B$9 -> 68 | Z14: =ROUND((W14+X14+Y14)*AI14,0) -> 134 | AA14: =INDEX(係数!$C$10:$C$12,MATCH(R14,係数!$A$10:$A$12,0)) -> 20 | AB14: =H14*(係数!$C$5+係数!$C$4*V14*(S14/60+係数!$C$6+Q14*係数!$C$7))+N14*係数!$C$13*係数!$C$4*V14*(S14/60+係数!$C$6+Q14*係数!$C$7) -> 101.27475 | AC14: =MAX(H14-1,0)*係数!$C$8+O14*係数!$C$9 -> 114 | AD14: =ROUND((AA14+AB14+AC14)*AI14,0) -> 235 | AE14: =INDEX(係数!$D$10:$D$12,MATCH(R14,係数!$A$10:$A$12,0)) -> 30 | AF14: =H14*(係数!$D$5+係数!$D$4*V14*(S14/60+係数!$D$6+Q14*係数!$D$7))+N14*係数!$D$13*係数!$D$4*V14*(S14/60+係数!$D$6+Q14*係数!$D$7) -> 153.09488 | AG14: =MAX(H14-1,0)*係数!$D$8+O14*係数!$D$9 -> 160 | AH14: =ROUND((AE14+AF14+AG14)*AI14,0) -> 343 | AI14: 1 | AJ14: =IF(G14>=AH14,"余裕あり",IF(G14>=AD14,"適正",IF(G14>=Z14,"ギリギリ","不足"))) -> 不足 | AK14: =G14-AD14 -> -115 | AL14: 0.33333333 | AM14: 0.41666667
A15: 12 | B15: 46329 | C15: D3a | D15: 同・一階廊下（図書室前） | E15: 屋内 | F15: （休み時間） | G15: 30 | H15: 1 | I15: 3 | J15: 3 | K15: 0 | L15: 0 | M15: 0 | N15: 1 | O15: 1 | P15: 0 | Q15: 0 | R15: 屋内新規 | S15: 45 | T15: 本・図書室の看板 | U15: 看板から下がり、正面に回り込む長回し。男の子の声は別録り | V15: =VLOOKUP(MIN(J15,3),係数!$A$19:$B$22,2,TRUE())*IF(L15=1,係数!$B$31,1)*VLOOKUP(M15,係数!$A$25:$B$28,2,TRUE())*IF(P15=1,係数!$B$32,1) -> 1.3 | W15: =INDEX(係数!$B$10:$B$12,MATCH(R15,係数!$A$10:$A$12,0)) -> 12 | X15: =H15*(係数!$B$5+係数!$B$4*V15*(S15/60+係数!$B$6+Q15*係数!$B$7))+N15*係数!$B$13*係数!$B$4*V15*(S15/60+係数!$B$6+Q15*係数!$B$7) -> 5.875 | Y15: =MAX(H15-1,0)*係数!$B$8+O15*係数!$B$9 -> 2 | Z15: =ROUND((W15+X15+Y15)*AI15,0) -> 20 | AA15: =INDEX(係数!$C$10:$C$12,MATCH(R15,係数!$A$10:$A$12,0)) -> 20 | AB15: =H15*(係数!$C$5+係数!$C$4*V15*(S15/60+係数!$C$6+Q15*係数!$C$7))+N15*係数!$C$13*係数!$C$4*V15*(S15/60+係数!$C$6+Q15*係数!$C$7) -> 10.5675 | AC15: =MAX(H15-1,0)*係数!$C$8+O15*係数!$C$9 -> 4 | AD15: =ROUND((AA15+AB15+AC15)*AI15,0) -> 35 | AE15: =INDEX(係数!$D$10:$D$12,MATCH(R15,係数!$A$10:$A$12,0)) -> 30 | AF15: =H15*(係数!$D$5+係数!$D$4*V15*(S15/60+係数!$D$6+Q15*係数!$D$7))+N15*係数!$D$13*係数!$D$4*V15*(S15/60+係数!$D$6+Q15*係数!$D$7) -> 15.30875 | AG15: =MAX(H15-1,0)*係数!$D$8+O15*係数!$D$9 -> 6 | AH15: =ROUND((AE15+AF15+AG15)*AI15,0) -> 51 | AI15: 1 | AJ15: =IF(G15>=AH15,"余裕あり",IF(G15>=AD15,"適正",IF(G15>=Z15,"ギリギリ","不足"))) -> ギリギリ | AK15: =G15-AD15 -> -5 | AL15: 0.42361111 | AM15: 0.44444444
A16: 14 | B16: 46329 | C16: D3a | D16: 同・廊下 | E16: 屋内 | F16: （休み時間） | G16: 30 | H16: 1 | I16: 3 | J16: 1 | K16: 0 | L16: 0 | M16: 0 | N16: 0 | O16: 0 | P16: 0 | Q16: 0 | R16: 同一継続 | S16: 15 | T16: 本 | U16: 18mmで顔、歪ませる | V16: =VLOOKUP(MIN(J16,3),係数!$A$19:$B$22,2,TRUE())*IF(L16=1,係数!$B$31,1)*VLOOKUP(M16,係数!$A$25:$B$28,2,TRUE())*IF(P16=1,係数!$B$32,1) -> 1.1 | W16: =INDEX(係数!$B$10:$B$12,MATCH(R16,係数!$A$10:$A$12,0)) -> 3 | X16: =H16*(係数!$B$5+係数!$B$4*V16*(S16/60+係数!$B$6+Q16*係数!$B$7))+N16*係数!$B$13*係数!$B$4*V16*(S16/60+係数!$B$6+Q16*係数!$B$7) -> 2.65 | Y16: =MAX(H16-1,0)*係数!$B$8+O16*係数!$B$9 -> 0 | Z16: =ROUND((W16+X16+Y16)*AI16,0) -> 6 | AA16: =INDEX(係数!$C$10:$C$12,MATCH(R16,係数!$A$10:$A$12,0)) -> 5 | AB16: =H16*(係数!$C$5+係数!$C$4*V16*(S16/60+係数!$C$6+Q16*係数!$C$7))+N16*係数!$C$13*係数!$C$4*V16*(S16/60+係数!$C$6+Q16*係数!$C$7) -> 4.965 | AC16: =MAX(H16-1,0)*係数!$C$8+O16*係数!$C$9 -> 0 | AD16: =ROUND((AA16+AB16+AC16)*AI16,0) -> 10 | AE16: =INDEX(係数!$D$10:$D$12,MATCH(R16,係数!$A$10:$A$12,0)) -> 8 | AF16: =H16*(係数!$D$5+係数!$D$4*V16*(S16/60+係数!$D$6+Q16*係数!$D$7))+N16*係数!$D$13*係数!$D$4*V16*(S16/60+係数!$D$6+Q16*係数!$D$7) -> 7.5825 | AG16: =MAX(H16-1,0)*係数!$D$8+O16*係数!$D$9 -> 0 | AH16: =ROUND((AE16+AF16+AG16)*AI16,0) -> 16 | AI16: 1 | AJ16: =IF(G16>=AH16,"余裕あり",IF(G16>=AD16,"適正",IF(G16>=Z16,"ギリギリ","不足"))) -> 余裕あり | AK16: =G16-AD16 -> 20 | AL16: 0.44444444 | AM16: 0.46527778
A17: 16 | B17: 46329 | C17: D3a | D17: 同・校庭（リョウ・ソウタ） | E17: 屋外 | F17: 昼過ぎ | G17: 60 | H17: 4 | I17: 10 | J17: 2 | K17: 0 | L17: 0 | M17: 0 | N17: 1 | O17: 4 | P17: 0 | Q17: 0 | R17: 屋外新規 | S17: 30 | T17: 石 | U17: B：100mm望遠／E：ワンカットで全部言う。背景に「遊んでいる生徒」が必要 | V17: =VLOOKUP(MIN(J17,3),係数!$A$19:$B$22,2,TRUE())*IF(L17=1,係数!$B$31,1)*VLOOKUP(M17,係数!$A$25:$B$28,2,TRUE())*IF(P17=1,係数!$B$32,1) -> 1.2 | W17: =INDEX(係数!$B$10:$B$12,MATCH(R17,係数!$A$10:$A$12,0)) -> 8 | X17: =H17*(係数!$B$5+係数!$B$4*V17*(S17/60+係数!$B$6+Q17*係数!$B$7))+N17*係数!$B$13*係数!$B$4*V17*(S17/60+係数!$B$6+Q17*係数!$B$7) -> 14.8 | Y17: =MAX(H17-1,0)*係数!$B$8+O17*係数!$B$9 -> 20 | Z17: =ROUND((W17+X17+Y17)*AI17,0) -> 43 | AA17: =INDEX(係数!$C$10:$C$12,MATCH(R17,係数!$A$10:$A$12,0)) -> 12 | AB17: =H17*(係数!$C$5+係数!$C$4*V17*(S17/60+係数!$C$6+Q17*係数!$C$7))+N17*係数!$C$13*係数!$C$4*V17*(S17/60+係数!$C$6+Q17*係数!$C$7) -> 27.06 | AC17: =MAX(H17-1,0)*係数!$C$8+O17*係数!$C$9 -> 34 | AD17: =ROUND((AA17+AB17+AC17)*AI17,0) -> 73 | AE17: =INDEX(係数!$D$10:$D$12,MATCH(R17,係数!$A$10:$A$12,0)) -> 18 | AF17: =H17*(係数!$D$5+係数!$D$4*V17*(S17/60+係数!$D$6+Q17*係数!$D$7))+N17*係数!$D$13*係数!$D$4*V17*(S17/60+係数!$D$6+Q17*係数!$D$7) -> 40.13 | AG17: =MAX(H17-1,0)*係数!$D$8+O17*係数!$D$9 -> 48 | AH17: =ROUND((AE17+AF17+AG17)*AI17,0) -> 106 | AI17: 1 | AJ17: =IF(G17>=AH17,"余裕あり",IF(G17>=AD17,"適正",IF(G17>=Z17,"ギリギリ","不足"))) -> ギリギリ | AK17: =G17-AD17 -> -13 | AL17: 0.5 | AM17: 0.54166667
A18: 11 | B18: 46329 | C18: D3a | D18: 同・廊下・階段 | E18: 屋内 | F18: 放課後直後 | G18: 60 | H18: 6 | I18: 6 | J18: 2 | K18: 0 | L18: 0 | M18: 0 | N18: 2 | O18: 1 | P18: 0 | Q18: 0 | R18: 屋内新規 | S18: 25 | T18: ポスター・本・筆箱 | U18: A：教室から階段までワンカットで後ろに下がる／D：50mmで目だけ最低20秒、ワンカットで振り向く | V18: =VLOOKUP(MIN(J18,3),係数!$A$19:$B$22,2,TRUE())*IF(L18=1,係数!$B$31,1)*VLOOKUP(M18,係数!$A$25:$B$28,2,TRUE())*IF(P18=1,係数!$B$32,1) -> 1.2 | W18: =INDEX(係数!$B$10:$B$12,MATCH(R18,係数!$A$10:$A$12,0)) -> 12 | X18: =H18*(係数!$B$5+係数!$B$4*V18*(S18/60+係数!$B$6+Q18*係数!$B$7))+N18*係数!$B$13*係数!$B$4*V18*(S18/60+係数!$B$6+Q18*係数!$B$7) -> 21.4 | Y18: =MAX(H18-1,0)*係数!$B$8+O18*係数!$B$9 -> 22 | Z18: =ROUND((W18+X18+Y18)*AI18,0) -> 55 | AA18: =INDEX(係数!$C$10:$C$12,MATCH(R18,係数!$A$10:$A$12,0)) -> 20 | AB18: =H18*(係数!$C$5+係数!$C$4*V18*(S18/60+係数!$C$6+Q18*係数!$C$7))+N18*係数!$C$13*係数!$C$4*V18*(S18/60+係数!$C$6+Q18*係数!$C$7) -> 39.66 | AC18: =MAX(H18-1,0)*係数!$C$8+O18*係数!$C$9 -> 34 | AD18: =ROUND((AA18+AB18+AC18)*AI18,0) -> 94 | AE18: =INDEX(係数!$D$10:$D$12,MATCH(R18,係数!$A$10:$A$12,0)) -> 30 | AF18: =H18*(係数!$D$5+係数!$D$4*V18*(S18/60+係数!$D$6+Q18*係数!$D$7))+N18*係数!$D$13*係数!$D$4*V18*(S18/60+係数!$D$6+Q18*係数!$D$7) -> 59.53 | AG18: =MAX(H18-1,0)*係数!$D$8+O18*係数!$D$9 -> 46 | AH18: =ROUND((AE18+AF18+AG18)*AI18,0) -> 136 | AI18: 1 | AJ18: =IF(G18>=AH18,"余裕あり",IF(G18>=AD18,"適正",IF(G18>=Z18,"ギリギリ","不足"))) -> ギリギリ | AK18: =G18-AD18 -> -34 | AL18: 0.54166667 | AM18: 0.58333333
A19: 19 | B19: 46329 | C19: D3b | D19: 同・下駄箱 | E19: 屋内 | F19: 夕方 | G19: 75 | H19: 3 | I19: 3 | J19: 2 | K19: 0 | L19: 0 | M19: 0 | N19: 0 | O19: 3 | P19: 0 | Q19: 0 | R19: 屋内新規 | S19: 20 | T19: 靴 | U19: 構図マーカーなし（3つと仮置き） | V19: =VLOOKUP(MIN(J19,3),係数!$A$19:$B$22,2,TRUE())*IF(L19=1,係数!$B$31,1)*VLOOKUP(M19,係数!$A$25:$B$28,2,TRUE())*IF(P19=1,係数!$B$32,1) -> 1.2 | W19: =INDEX(係数!$B$10:$B$12,MATCH(R19,係数!$A$10:$A$12,0)) -> 12 | X19: =H19*(係数!$B$5+係数!$B$4*V19*(S19/60+係数!$B$6+Q19*係数!$B$7))+N19*係数!$B$13*係数!$B$4*V19*(S19/60+係数!$B$6+Q19*係数!$B$7) -> 9 | Y19: =MAX(H19-1,0)*係数!$B$8+O19*係数!$B$9 -> 14 | Z19: =ROUND((W19+X19+Y19)*AI19,0) -> 35 | AA19: =INDEX(係数!$C$10:$C$12,MATCH(R19,係数!$A$10:$A$12,0)) -> 20 | AB19: =H19*(係数!$C$5+係数!$C$4*V19*(S19/60+係数!$C$6+Q19*係数!$C$7))+N19*係数!$C$13*係数!$C$4*V19*(S19/60+係数!$C$6+Q19*係数!$C$7) -> 16.74 | AC19: =MAX(H19-1,0)*係数!$C$8+O19*係数!$C$9 -> 24 | AD19: =ROUND((AA19+AB19+AC19)*AI19,0) -> 61 | AE19: =INDEX(係数!$D$10:$D$12,MATCH(R19,係数!$A$10:$A$12,0)) -> 30 | AF19: =H19*(係数!$D$5+係数!$D$4*V19*(S19/60+係数!$D$6+Q19*係数!$D$7))+N19*係数!$D$13*係数!$D$4*V19*(S19/60+係数!$D$6+Q19*係数!$D$7) -> 25.32 | AG19: =MAX(H19-1,0)*係数!$D$8+O19*係数!$D$9 -> 34 | AH19: =ROUND((AE19+AF19+AG19)*AI19,0) -> 89 | AI19: 1 | AJ19: =IF(G19>=AH19,"余裕あり",IF(G19>=AD19,"適正",IF(G19>=Z19,"ギリギリ","不足"))) -> 適正 | AK19: =G19-AD19 -> 14 | AL19: 0.63541667 | AM19: 0.6875
A20: 17 | B20: 46329 | C20: D3b | D20: 同・外（空） | E20: 屋外 | F20: 夕方（夕焼け） | G20: 30 | H20: 1 | I20: 0 | J20: 0 | K20: 0 | L20: 0 | M20: 0 | N20: 0 | O20: 0 | P20: 0 | Q20: 0 | R20: 屋外新規 | S20: 15 | U20: 廊下から校庭側の空 | V20: =VLOOKUP(MIN(J20,3),係数!$A$19:$B$22,2,TRUE())*IF(L20=1,係数!$B$31,1)*VLOOKUP(M20,係数!$A$25:$B$28,2,TRUE())*IF(P20=1,係数!$B$32,1) -> 1 | W20: =INDEX(係数!$B$10:$B$12,MATCH(R20,係数!$A$10:$A$12,0)) -> 8 | X20: =H20*(係数!$B$5+係数!$B$4*V20*(S20/60+係数!$B$6+Q20*係数!$B$7))+N20*係数!$B$13*係数!$B$4*V20*(S20/60+係数!$B$6+Q20*係数!$B$7) -> 2.5 | Y20: =MAX(H20-1,0)*係数!$B$8+O20*係数!$B$9 -> 0 | Z20: =ROUND((W20+X20+Y20)*AI20,0) -> 11 | AA20: =INDEX(係数!$C$10:$C$12,MATCH(R20,係数!$A$10:$A$12,0)) -> 12 | AB20: =H20*(係数!$C$5+係数!$C$4*V20*(S20/60+係数!$C$6+Q20*係数!$C$7))+N20*係数!$C$13*係数!$C$4*V20*(S20/60+係数!$C$6+Q20*係数!$C$7) -> 4.65 | AC20: =MAX(H20-1,0)*係数!$C$8+O20*係数!$C$9 -> 0 | AD20: =ROUND((AA20+AB20+AC20)*AI20,0) -> 17 | AE20: =INDEX(係数!$D$10:$D$12,MATCH(R20,係数!$A$10:$A$12,0)) -> 18 | AF20: =H20*(係数!$D$5+係数!$D$4*V20*(S20/60+係数!$D$6+Q20*係数!$D$7))+N20*係数!$D$13*係数!$D$4*V20*(S20/60+係数!$D$6+Q20*係数!$D$7) -> 7.075 | AG20: =MAX(H20-1,0)*係数!$D$8+O20*係数!$D$9 -> 0 | AH20: =ROUND((AE20+AF20+AG20)*AI20,0) -> 25 | AI20: 1 | AJ20: =IF(G20>=AH20,"余裕あり",IF(G20>=AD20,"適正",IF(G20>=Z20,"ギリギリ","不足"))) -> 余裕あり | AK20: =G20-AD20 -> 13 | AL20: 0.6875 | AM20: 0.70833333
A21: 20 | B21: 46333 | C21: D4a | D21: 田舎の通り | E21: 屋外 | F21: 夕方 | G21: 30 | H21: 2 | I21: 5 | J21: 2 | K21: 0 | L21: 0 | M21: 0 | N21: 0 | O21: 2 | P21: 0 | Q21: 0 | R21: 屋外新規 | S21: 25 | T21: ランドセル | U21: 構図マーカーなし（2つと仮置き） | V21: =VLOOKUP(MIN(J21,3),係数!$A$19:$B$22,2,TRUE())*IF(L21=1,係数!$B$31,1)*VLOOKUP(M21,係数!$A$25:$B$28,2,TRUE())*IF(P21=1,係数!$B$32,1) -> 1.2 | W21: =INDEX(係数!$B$10:$B$12,MATCH(R21,係数!$A$10:$A$12,0)) -> 8 | X21: =H21*(係数!$B$5+係数!$B$4*V21*(S21/60+係数!$B$6+Q21*係数!$B$7))+N21*係数!$B$13*係数!$B$4*V21*(S21/60+係数!$B$6+Q21*係数!$B$7) -> 6.4 | Y21: =MAX(H21-1,0)*係数!$B$8+O21*係数!$B$9 -> 8 | Z21: =ROUND((W21+X21+Y21)*AI21,0) -> 22 | AA21: =INDEX(係数!$C$10:$C$12,MATCH(R21,係数!$A$10:$A$12,0)) -> 12 | AB21: =H21*(係数!$C$5+係数!$C$4*V21*(S21/60+係数!$C$6+Q21*係数!$C$7))+N21*係数!$C$13*係数!$C$4*V21*(S21/60+係数!$C$6+Q21*係数!$C$7) -> 11.76 | AC21: =MAX(H21-1,0)*係数!$C$8+O21*係数!$C$9 -> 14 | AD21: =ROUND((AA21+AB21+AC21)*AI21,0) -> 38 | AE21: =INDEX(係数!$D$10:$D$12,MATCH(R21,係数!$A$10:$A$12,0)) -> 18 | AF21: =H21*(係数!$D$5+係数!$D$4*V21*(S21/60+係数!$D$6+Q21*係数!$D$7))+N21*係数!$D$13*係数!$D$4*V21*(S21/60+係数!$D$6+Q21*係数!$D$7) -> 17.58 | AG21: =MAX(H21-1,0)*係数!$D$8+O21*係数!$D$9 -> 20 | AH21: =ROUND((AE21+AF21+AG21)*AI21,0) -> 56 | AI21: 1 | AJ21: =IF(G21>=AH21,"余裕あり",IF(G21>=AD21,"適正",IF(G21>=Z21,"ギリギリ","不足"))) -> ギリギリ | AK21: =G21-AD21 -> -8 | AL21: 0.45833333 | AM21: 0.47916667
A22: 2 | B22: 46333 | C22: D4a | D22: 田舎の通り | E22: 屋外 | F22: 朝 | G22: 90 | H22: 13 | I22: 21 | J22: 2 | K22: 1 | L22: 1 | M22: 0 | N22: 1 | O22: 0 | P22: 0 | Q22: 0 | R22: 同一継続 | S22: 15 | T22: ランドセル・リード・犬（パンチ） | U22: 構図A〜M。B：カメラが後ろへ下がりながら歩き芝居。犬の芝居（C・E〜L） | V22: =VLOOKUP(MIN(J22,3),係数!$A$19:$B$22,2,TRUE())*IF(L22=1,係数!$B$31,1)*VLOOKUP(M22,係数!$A$25:$B$28,2,TRUE())*IF(P22=1,係数!$B$32,1) -> 1.8 | W22: =INDEX(係数!$B$10:$B$12,MATCH(R22,係数!$A$10:$A$12,0)) -> 3 | X22: =H22*(係数!$B$5+係数!$B$4*V22*(S22/60+係数!$B$6+Q22*係数!$B$7))+N22*係数!$B$13*係数!$B$4*V22*(S22/60+係数!$B$6+Q22*係数!$B$7) -> 49.45 | Y22: =MAX(H22-1,0)*係数!$B$8+O22*係数!$B$9 -> 48 | Z22: =ROUND((W22+X22+Y22)*AI22,0) -> 100 | AA22: =INDEX(係数!$C$10:$C$12,MATCH(R22,係数!$A$10:$A$12,0)) -> 5 | AB22: =H22*(係数!$C$5+係数!$C$4*V22*(S22/60+係数!$C$6+Q22*係数!$C$7))+N22*係数!$C$13*係数!$C$4*V22*(S22/60+係数!$C$6+Q22*係数!$C$7) -> 96.045 | AC22: =MAX(H22-1,0)*係数!$C$8+O22*係数!$C$9 -> 72 | AD22: =ROUND((AA22+AB22+AC22)*AI22,0) -> 173 | AE22: =INDEX(係数!$D$10:$D$12,MATCH(R22,係数!$A$10:$A$12,0)) -> 8 | AF22: =H22*(係数!$D$5+係数!$D$4*V22*(S22/60+係数!$D$6+Q22*係数!$D$7))+N22*係数!$D$13*係数!$D$4*V22*(S22/60+係数!$D$6+Q22*係数!$D$7) -> 149.3225 | AG22: =MAX(H22-1,0)*係数!$D$8+O22*係数!$D$9 -> 96 | AH22: =ROUND((AE22+AF22+AG22)*AI22,0) -> 253 | AI22: 1 | AJ22: =IF(G22>=AH22,"余裕あり",IF(G22>=AD22,"適正",IF(G22>=Z22,"ギリギリ","不足"))) -> 不足 | AK22: =G22-AD22 -> -83 | AL22: 0.48611111 | AM22: 0.54861111
A23: 21 | B23: 46333 | C23: D4a | D23: 通り（脚本）／防波堤（現行表） | E23: 屋外 | F23: 夕方 | G23: 75 | H23: 3 | I23: 15 | J23: 2 | K23: 0 | L23: 0 | M23: 0 | N23: 1 | O23: 3 | P23: 0 | Q23: 0 | R23: 屋外新規 | S23: 40 | T23: ランドセル | U23: 構図マーカーなし（3つと仮置き）。歩きながらの会話 | V23: =VLOOKUP(MIN(J23,3),係数!$A$19:$B$22,2,TRUE())*IF(L23=1,係数!$B$31,1)*VLOOKUP(M23,係数!$A$25:$B$28,2,TRUE())*IF(P23=1,係数!$B$32,1) -> 1.2 | W23: =INDEX(係数!$B$10:$B$12,MATCH(R23,係数!$A$10:$A$12,0)) -> 8 | X23: =H23*(係数!$B$5+係数!$B$4*V23*(S23/60+係数!$B$6+Q23*係数!$B$7))+N23*係数!$B$13*係数!$B$4*V23*(S23/60+係数!$B$6+Q23*係数!$B$7) -> 12.8 | Y23: =MAX(H23-1,0)*係数!$B$8+O23*係数!$B$9 -> 14 | Z23: =ROUND((W23+X23+Y23)*AI23,0) -> 35 | AA23: =INDEX(係数!$C$10:$C$12,MATCH(R23,係数!$A$10:$A$12,0)) -> 12 | AB23: =H23*(係数!$C$5+係数!$C$4*V23*(S23/60+係数!$C$6+Q23*係数!$C$7))+N23*係数!$C$13*係数!$C$4*V23*(S23/60+係数!$C$6+Q23*係数!$C$7) -> 22.98 | AC23: =MAX(H23-1,0)*係数!$C$8+O23*係数!$C$9 -> 24 | AD23: =ROUND((AA23+AB23+AC23)*AI23,0) -> 59 | AE23: =INDEX(係数!$D$10:$D$12,MATCH(R23,係数!$A$10:$A$12,0)) -> 18 | AF23: =H23*(係数!$D$5+係数!$D$4*V23*(S23/60+係数!$D$6+Q23*係数!$D$7))+N23*係数!$D$13*係数!$D$4*V23*(S23/60+係数!$D$6+Q23*係数!$D$7) -> 33.44 | AG23: =MAX(H23-1,0)*係数!$D$8+O23*係数!$D$9 -> 34 | AH23: =ROUND((AE23+AF23+AG23)*AI23,0) -> 85 | AI23: 1 | AJ23: =IF(G23>=AH23,"余裕あり",IF(G23>=AD23,"適正",IF(G23>=Z23,"ギリギリ","不足"))) -> 適正 | AK23: =G23-AD23 -> 16 | AL23: 0.60416667 | AM23: 0.65625
A24: 22 | B24: 46333 | C24: D4a | D24: 海（砂浜） | E24: 屋外 | F24: 夕方 | G24: 15 | H24: 2 | I24: 2 | J24: 2 | K24: 0 | L24: 0 | M24: 0 | N24: 0 | O24: 2 | P24: 0 | Q24: 1 | R24: 屋外新規 | S24: 20 | T24: ランドセル | U24: 全力で走る。砂浜の足跡を消すリセットが必要。波音は別録り | V24: =VLOOKUP(MIN(J24,3),係数!$A$19:$B$22,2,TRUE())*IF(L24=1,係数!$B$31,1)*VLOOKUP(M24,係数!$A$25:$B$28,2,TRUE())*IF(P24=1,係数!$B$32,1) -> 1.2 | W24: =INDEX(係数!$B$10:$B$12,MATCH(R24,係数!$A$10:$A$12,0)) -> 8 | X24: =H24*(係数!$B$5+係数!$B$4*V24*(S24/60+係数!$B$6+Q24*係数!$B$7))+N24*係数!$B$13*係数!$B$4*V24*(S24/60+係数!$B$6+Q24*係数!$B$7) -> 13.2 | Y24: =MAX(H24-1,0)*係数!$B$8+O24*係数!$B$9 -> 8 | Z24: =ROUND((W24+X24+Y24)*AI24,0) -> 29 | AA24: =INDEX(係数!$C$10:$C$12,MATCH(R24,係数!$A$10:$A$12,0)) -> 12 | AB24: =H24*(係数!$C$5+係数!$C$4*V24*(S24/60+係数!$C$6+Q24*係数!$C$7))+N24*係数!$C$13*係数!$C$4*V24*(S24/60+係数!$C$6+Q24*係数!$C$7) -> 29.16 | AC24: =MAX(H24-1,0)*係数!$C$8+O24*係数!$C$9 -> 14 | AD24: =ROUND((AA24+AB24+AC24)*AI24,0) -> 55 | AE24: =INDEX(係数!$D$10:$D$12,MATCH(R24,係数!$A$10:$A$12,0)) -> 18 | AF24: =H24*(係数!$D$5+係数!$D$4*V24*(S24/60+係数!$D$6+Q24*係数!$D$7))+N24*係数!$D$13*係数!$D$4*V24*(S24/60+係数!$D$6+Q24*係数!$D$7) -> 50.48 | AG24: =MAX(H24-1,0)*係数!$D$8+O24*係数!$D$9 -> 20 | AH24: =ROUND((AE24+AF24+AG24)*AI24,0) -> 88 | AI24: 1 | AJ24: =IF(G24>=AH24,"余裕あり",IF(G24>=AD24,"適正",IF(G24>=Z24,"ギリギリ","不足"))) -> 不足 | AK24: =G24-AD24 -> -40 | AL24: 0.67013889 | AM24: 0.68055556
A25: 1 | B25: 46333 | C25: D4b | D25: 砂浜（脚本）／防波堤（現行表） | E25: 屋外 | F25: 夕方（夕焼け） | G25: 45 | H25: 1 | I25: 0 | J25: 2 | K25: 0 | L25: 0 | M25: 0 | N25: 1 | O25: 1 | P25: 0 | Q25: 0 | R25: 屋外新規 | S25: 30 | T25: ランドセル | U25: 18mm広角で背中に寄っていく。オレンジ色の夕焼け | V25: =VLOOKUP(MIN(J25,3),係数!$A$19:$B$22,2,TRUE())*IF(L25=1,係数!$B$31,1)*VLOOKUP(M25,係数!$A$25:$B$28,2,TRUE())*IF(P25=1,係数!$B$32,1) -> 1.2 | W25: =INDEX(係数!$B$10:$B$12,MATCH(R25,係数!$A$10:$A$12,0)) -> 8 | X25: =H25*(係数!$B$5+係数!$B$4*V25*(S25/60+係数!$B$6+Q25*係数!$B$7))+N25*係数!$B$13*係数!$B$4*V25*(S25/60+係数!$B$6+Q25*係数!$B$7) -> 4.6 | Y25: =MAX(H25-1,0)*係数!$B$8+O25*係数!$B$9 -> 2 | Z25: =ROUND((W25+X25+Y25)*AI25,0) -> 15 | AA25: =INDEX(係数!$C$10:$C$12,MATCH(R25,係数!$A$10:$A$12,0)) -> 12 | AB25: =H25*(係数!$C$5+係数!$C$4*V25*(S25/60+係数!$C$6+Q25*係数!$C$7))+N25*係数!$C$13*係数!$C$4*V25*(S25/60+係数!$C$6+Q25*係数!$C$7) -> 8.52 | AC25: =MAX(H25-1,0)*係数!$C$8+O25*係数!$C$9 -> 4 | AD25: =ROUND((AA25+AB25+AC25)*AI25,0) -> 25 | AE25: =INDEX(係数!$D$10:$D$12,MATCH(R25,係数!$A$10:$A$12,0)) -> 18 | AF25: =H25*(係数!$D$5+係数!$D$4*V25*(S25/60+係数!$D$6+Q25*係数!$D$7))+N25*係数!$D$13*係数!$D$4*V25*(S25/60+係数!$D$6+Q25*係数!$D$7) -> 12.71 | AG25: =MAX(H25-1,0)*係数!$D$8+O25*係数!$D$9 -> 6 | AH25: =ROUND((AE25+AF25+AG25)*AI25,0) -> 37 | AI25: 1 | AJ25: =IF(G25>=AH25,"余裕あり",IF(G25>=AD25,"適正",IF(G25>=Z25,"ギリギリ","不足"))) -> 余裕あり | AK25: =G25-AD25 -> 20 | AL25: 0.6875 | AM25: 0.71875
A26: 合計 | G26: =SUM(G4:G25) -> 1120 | Z26: =SUM(Z4:Z25) -> 783 | AD26: =SUM(AD4:AD25) -> 1355 | AH26: =SUM(AH4:AH25) -> 2002

Sheet 移動
A1: 学校内・ロケ地間の移動と切り替え（分）※校舎の距離は未測定のため仮定
A3: 移動の種類 | B3: 最短 | C3: 標準 | D3: 最長 | H3: 仮定の内容
A4: 同一場所 | B4: 0 | C4: 3 | D4: 5 | H4: 同じ場所で向きだけ変える
A5: その場転換 | B5: 5 | C5: 10 | D5: 15 | H5: 同じ教室で時計・黒板・机・ランドセルを変える（時間経過）
A6: 同一フロア | B6: 5 | C6: 8 | D6: 12 | H6: 機材を持って同じ階の隣の場所へ
A7: 校舎内別フロア | B7: 8 | C7: 12 | D7: 18 | H7: 階段で機材を上げ下ろし
A8: 校舎↔屋外 | B8: 10 | C8: 15 | D8: 20 | H8: 校舎と校門・校庭の行き来
A9: 校舎↔体育館 | B9: 10 | C9: 15 | D9: 25 | H9: 渡り廊下・靴の履き替えを含む
A10: 車移動（長） | B10: 20 | C10: 30 | D10: 45 | H10: 通り→防波堤（現行表は30分）
A11: 車移動（短） | B11: 10 | C11: 20 | D11: 30 | H11: 防波堤→海（現行表は20分・準備込み）
A12: 浜の中で移動 | B12: 0 | C12: 5 | D12: 15 | H12: S22とS1が同じ浜なら最短0
A15: ブロック | B15: 区間 | C15: 移動の種類 | D15: 最短 | E15: 標準 | F15: 最長 | G15: 現行表で取っている時間
A16: D1 | B16: S3 校門 → S4 階段 | C16: 校舎↔屋外 | D16: =INDEX($B$4:$B$12,MATCH($C16,$A$4:$A$12,0)) -> 10 | E16: =INDEX($C$4:$C$12,MATCH($C16,$A$4:$A$12,0)) -> 15 | F16: =INDEX($D$4:$D$12,MATCH($C16,$A$4:$A$12,0)) -> 20 | G16: 10
A17: D1 | B17: S4 階段 →（昼食）→ S16A 校庭 | C17: 校舎↔屋外 | D17: =INDEX($B$4:$B$12,MATCH($C17,$A$4:$A$12,0)) -> 10 | E17: =INDEX($C$4:$C$12,MATCH($C17,$A$4:$A$12,0)) -> 15 | F17: =INDEX($D$4:$D$12,MATCH($C17,$A$4:$A$12,0)) -> 20 | G17: 0
A18: D1 | B18: S16A → S13 同じ校庭 | C18: 同一場所 | D18: =INDEX($B$4:$B$12,MATCH($C18,$A$4:$A$12,0)) -> 0 | E18: =INDEX($C$4:$C$12,MATCH($C18,$A$4:$A$12,0)) -> 3 | F18: =INDEX($D$4:$D$12,MATCH($C18,$A$4:$A$12,0)) -> 5 | G18: 10
A19: D2a | B19: S5 → S6 時計・黒板の変更 | C19: その場転換 | D19: =INDEX($B$4:$B$12,MATCH($C19,$A$4:$A$12,0)) -> 5 | E19: =INDEX($C$4:$C$12,MATCH($C19,$A$4:$A$12,0)) -> 10 | F19: =INDEX($D$4:$D$12,MATCH($C19,$A$4:$A$12,0)) -> 15 | G19: 10
A20: D2a | B20: S6 → S8 時計・黒板の変更 | C20: その場転換 | D20: =INDEX($B$4:$B$12,MATCH($C20,$A$4:$A$12,0)) -> 5 | E20: =INDEX($C$4:$C$12,MATCH($C20,$A$4:$A$12,0)) -> 10 | F20: =INDEX($D$4:$D$12,MATCH($C20,$A$4:$A$12,0)) -> 15 | G20: 0
A21: D2a | B21: S8 教室 → S9 廊下 | C21: 同一フロア | D21: =INDEX($B$4:$B$12,MATCH($C21,$A$4:$A$12,0)) -> 5 | E21: =INDEX($C$4:$C$12,MATCH($C21,$A$4:$A$12,0)) -> 8 | F21: =INDEX($D$4:$D$12,MATCH($C21,$A$4:$A$12,0)) -> 12 | G21: 0
A22: D2a | B22: S9 廊下 → S10 教室（机を散らかす） | C22: 同一フロア | D22: =INDEX($B$4:$B$12,MATCH($C22,$A$4:$A$12,0)) -> 5 | E22: =INDEX($C$4:$C$12,MATCH($C22,$A$4:$A$12,0)) -> 8 | F22: =INDEX($D$4:$D$12,MATCH($C22,$A$4:$A$12,0)) -> 12 | G22: 0
A23: D2b | B23: S10 → S18 帰りの会（ランドセル・黒板） | C23: その場転換 | D23: =INDEX($B$4:$B$12,MATCH($C23,$A$4:$A$12,0)) -> 5 | E23: =INDEX($C$4:$C$12,MATCH($C23,$A$4:$A$12,0)) -> 10 | F23: =INDEX($D$4:$D$12,MATCH($C23,$A$4:$A$12,0)) -> 15 | G23: 0
A24: D3a | B24: S15 体育館 → S12 一階廊下 | C24: 校舎↔体育館 | D24: =INDEX($B$4:$B$12,MATCH($C24,$A$4:$A$12,0)) -> 10 | E24: =INDEX($C$4:$C$12,MATCH($C24,$A$4:$A$12,0)) -> 15 | F24: =INDEX($D$4:$D$12,MATCH($C24,$A$4:$A$12,0)) -> 25 | G24: 10
A25: D3a | B25: S12 → S14 廊下 | C25: 同一フロア | D25: =INDEX($B$4:$B$12,MATCH($C25,$A$4:$A$12,0)) -> 5 | E25: =INDEX($C$4:$C$12,MATCH($C25,$A$4:$A$12,0)) -> 8 | F25: =INDEX($D$4:$D$12,MATCH($C25,$A$4:$A$12,0)) -> 12 | G25: 0
A26: D3a | B26: S14 →（昼食）→ S16 校庭 | C26: 校舎↔屋外 | D26: =INDEX($B$4:$B$12,MATCH($C26,$A$4:$A$12,0)) -> 10 | E26: =INDEX($C$4:$C$12,MATCH($C26,$A$4:$A$12,0)) -> 15 | F26: =INDEX($D$4:$D$12,MATCH($C26,$A$4:$A$12,0)) -> 20 | G26: 0
A27: D3a | B27: S16 校庭 → S11 廊下・階段（2階） | C27: 校舎↔屋外 | D27: =INDEX($B$4:$B$12,MATCH($C27,$A$4:$A$12,0)) -> 10 | E27: =INDEX($C$4:$C$12,MATCH($C27,$A$4:$A$12,0)) -> 15 | F27: =INDEX($D$4:$D$12,MATCH($C27,$A$4:$A$12,0)) -> 20 | G27: 0
... A32: D4a | B32: S22 海 → S1 防波堤／砂浜 | C32: 浜の中で移動 | D32: =INDEX($B$4:$B$12,MATCH($C32,$A$4:$A$12,0)) -> 0 | E32: =INDEX($C$4:$C$12,MATCH($C32,$A$4:$A$12,0)) -> 5 | F32: =INDEX($D$4:$D$12,MATCH($C32,$A$4:$A$12,0)) -> 15 | G32: 10
A35: ロケハン（10/29・10/30）で測る項目
A36: 1 | B36: 校門→階段→2階教室の歩行時間（機材あり・台車あり）
A37: 2 | B37: 2階教室→廊下→階段（S11の動線）の距離と、カメラが後ろに下がれる幅
A38: 3 | B38: 1階廊下（図書室前・S12）→体育館の距離、渡り廊下の有無、靴の履き替え場所
A39: 4 | B39: 体育館の天井通路（S15構図G）に上がれるか、安全柵、上がるまでの時間
A40: 5 | B40: 校舎→校庭（S16・S13）の距離、電源の取り方
A41: 6 | B41: 下駄箱（S19）の向き（西日が入るか）と、夕方に外が見えるか
A42: 7 | B42: S17の空：廊下から校庭側の空が西〜南西を向いているか
A43: 8 | B43: 各教室・廊下・体育館のルームトーン（環境音）と、近くの道路・換気扇の音
A44: 9 | B44: 教室の時計を動かせるか（S6・S8・S18の時刻合わせ）、黒板を使ってよいか
A45: 10 | B45: 機材置き場（ベース）から各場所までの距離、トイレ・控室（子ども用）の位置
A46: 11 | B46: 通り（S2・S20）の交通量、犬の散歩ルートの安全、撮影許可の範囲
A47: 12 | B47: 通り→防波堤→海の車移動時間、駐車場所から撮影場所までの歩き時間
... A49: 14 | B49: S1の位置で、日没の方角（西南西）に海が見えるか

Sheet 日没
A1: 日没と夕方シーンの照合
A3: 日付 | B3: 11/7との差(分) | C3: 日没（推定） | D3: メモ
A4: 46333 | B4: 0 | C4: 0.71388889 | D4: 現行表の値「日没17:08ごろ」。ロケ地の正確な日没を要確認
A5: 46326 | B5: 7 | C5: =$C$4+B5/1440 -> 0.71875 | D5: 北緯34度付近で計算した日ごとの差（NOAAの式）
A6: 46327 | B6: 6 | C6: =$C$4+B6/1440 -> 0.71805556 | D6: 北緯34度付近で計算した日ごとの差（NOAAの式）
A7: 46329 | B7: 4 | C7: =$C$4+B7/1440 -> 0.71666667 | D7: 北緯34度付近で計算した日ごとの差（NOAAの式）
A8: 46334 | B8: -1 | C8: =$C$4+B8/1440 -> 0.71319444 | D8: 北緯34度付近で計算した日ごとの差（NOAAの式）
A10: 時間帯の窓 | B10: 日没からの開始(分) | C10: 日没からの終了(分) | D10: 意味
A11: 夕方の光 | B11: -90 | C11: 0 | D11: 日が低く、オレンジがかった光（日没90分前〜日没）
A12: 夕焼けの空 | B12: -15 | C12: 20 | D12: 空がオレンジに染まる時間（日没15分前〜20分後）
A14: S | B14: 日付 | C14: 時間帯（脚本） | D14: 窓の種類 | E14: 現行の開始 | F14: 現行の終了 | G14: 日没 | H14: 窓の開始 | I14: 窓の終了 | J14: 判定
A15: 17 | B15: 46329 | C15: 夕方（夕焼け） | D15: 夕焼けの空 | E15: =INDEX(シーン見積!$AL$4:$AL$25,MATCH(A15,シーン見積!$A$4:$A$25,0)) -> 0.6875 | F15: =INDEX(シーン見積!$AM$4:$AM$25,MATCH(A15,シーン見積!$A$4:$A$25,0)) -> 0.70833333 | G15: =INDEX($C$4:$C$8,MATCH(B15,$A$4:$A$8,0)) -> 0.71666667 | H15: =G15+INDEX($B$11:$B$12,MATCH(D15,$A$11:$A$12,0))/1440 -> 0.70625 | I15: =G15+INDEX($C$11:$C$12,MATCH(D15,$A$11:$A$12,0))/1440 -> 0.73055556 | J15: =IF(AND(E15>=H15-1/1440/2,F15<=I15+1/1440/2),"OK",IF(OR(F15<=H15,E15>=I15),"ずれ","一部ずれ")) -> 一部ずれ
A16: 19 | B16: 46329 | C16: 夕方 | D16: 夕方の光 | E16: =INDEX(シーン見積!$AL$4:$AL$25,MATCH(A16,シーン見積!$A$4:$A$25,0)) -> 0.63541667 | F16: =INDEX(シーン見積!$AM$4:$AM$25,MATCH(A16,シーン見積!$A$4:$A$25,0)) -> 0.6875 | G16: =INDEX($C$4:$C$8,MATCH(B16,$A$4:$A$8,0)) -> 0.71666667 | H16: =G16+INDEX($B$11:$B$12,MATCH(D16,$A$11:$A$12,0))/1440 -> 0.65416667 | I16: =G16+INDEX($C$11:$C$12,MATCH(D16,$A$11:$A$12,0))/1440 -> 0.71666667 | J16: =IF(AND(E16>=H16-1/1440/2,F16<=I16+1/1440/2),"OK",IF(OR(F16<=H16,E16>=I16),"ずれ","一部ずれ")) -> 一部ずれ
A17: 20 | B17: 46333 | C17: 夕方 | D17: 夕方の光 | E17: =INDEX(シーン見積!$AL$4:$AL$25,MATCH(A17,シーン見積!$A$4:$A$25,0)) -> 0.45833333 | F17: =INDEX(シーン見積!$AM$4:$AM$25,MATCH(A17,シーン見積!$A$4:$A$25,0)) -> 0.47916667 | G17: =INDEX($C$4:$C$8,MATCH(B17,$A$4:$A$8,0)) -> 0.71388889 | H17: =G17+INDEX($B$11:$B$12,MATCH(D17,$A$11:$A$12,0))/1440 -> 0.65138889 | I17: =G17+INDEX($C$11:$C$12,MATCH(D17,$A$11:$A$12,0))/1440 -> 0.71388889 | J17: =IF(AND(E17>=H17-1/1440/2,F17<=I17+1/1440/2),"OK",IF(OR(F17<=H17,E17>=I17),"ずれ","一部ずれ")) -> ずれ
A18: 21 | B18: 46333 | C18: 夕方 | D18: 夕方の光 | E18: =INDEX(シーン見積!$AL$4:$AL$25,MATCH(A18,シーン見積!$A$4:$A$25,0)) -> 0.60416667 | F18: =INDEX(シーン見積!$AM$4:$AM$25,MATCH(A18,シーン見積!$A$4:$A$25,0)) -> 0.65625 | G18: =INDEX($C$4:$C$8,MATCH(B18,$A$4:$A$8,0)) -> 0.71388889 | H18: =G18+INDEX($B$11:$B$12,MATCH(D18,$A$11:$A$12,0))/1440 -> 0.65138889 | I18: =G18+INDEX($C$11:$C$12,MATCH(D18,$A$11:$A$12,0))/1440 -> 0.71388889 | J18: =IF(AND(E18>=H18-1/1440/2,F18<=I18+1/1440/2),"OK",IF(OR(F18<=H18,E18>=I18),"ずれ","一部ずれ")) -> 一部ずれ
A19: 22 | B19: 46333 | C19: 夕方 | D19: 夕方の光 | E19: =INDEX(シーン見積!$AL$4:$AL$25,MATCH(A19,シーン見積!$A$4:$A$25,0)) -> 0.67013889 | F19: =INDEX(シーン見積!$AM$4:$AM$25,MATCH(A19,シーン見積!$A$4:$A$25,0)) -> 0.68055556 | G19: =INDEX($C$4:$C$8,MATCH(B19,$A$4:$A$8,0)) -> 0.71388889 | H19: =G19+INDEX($B$11:$B$12,MATCH(D19,$A$11:$A$12,0))/1440 -> 0.65138889 | I19: =G19+INDEX($C$11:$C$12,MATCH(D19,$A$11:$A$12,0))/1440 -> 0.71388889 | J19: =IF(AND(E19>=H19-1/1440/2,F19<=I19+1/1440/2),"OK",IF(OR(F19<=H19,E19>=I19),"ずれ","一部ずれ")) -> OK
A20: 1 | B20: 46333 | C20: 夕方（夕焼け） | D20: 夕焼けの空 | E20: =INDEX(シーン見積!$AL$4:$AL$25,MATCH(A20,シーン見積!$A$4:$A$25,0)) -> 0.6875 | F20: =INDEX(シーン見積!$AM$4:$AM$25,MATCH(A20,シーン見積!$A$4:$A$25,0)) -> 0.71875 | G20: =INDEX($C$4:$C$8,MATCH(B20,$A$4:$A$8,0)) -> 0.71388889 | H20: =G20+INDEX($B$11:$B$12,MATCH(D20,$A$11:$A$12,0))/1440 -> 0.70347222 | I20: =G20+INDEX($C$11:$C$12,MATCH(D20,$A$11:$A$12,0))/1440 -> 0.72777778 | J20: =IF(AND(E20>=H20-1/1440/2,F20<=I20+1/1440/2),"OK",IF(OR(F20<=H20,E20>=I20),"ずれ","一部ずれ")) -> 一部ずれ
A22: ※朝のシーン（S3 11:30・S2 11:40〜）は、太陽が高い時間です。影が短くなるので、朝らしさが出にくい点に注意。

Sheet 日別
A1: 日ごと（ブロックごと）の使える時間と必要時間
A2: ブロック＝光や日没で開始時刻が決まる区切り。終了予測＝MAX(ブロック開始, 前のブロックの終了予測)＋昼食＋必要時間。
A4: ブロック | B4: 日付 | C4: 開始 | D4: 終了の上限 | E4: 昼食(分) | F4: 使える時間(分) | G4: 現行のシーン枠(分) | H4: 現行の移動(分) | I4: 現行の予備・待ち(分) | J4: ピンマイク作業人数 | K4: 必要:最短 | L4: 必要:標準 | M4: 必要:余裕 | N4: 余白:最短 | O4: 余白:標準 | P4: 余白:余裕 | Q4: 予備の消費:標準 | R4: 予備の消費:余裕 | S4: 終了予測:最短 | T4: 終了予測:標準 | U4: 終了予測:余裕 | V4: 判定(標準) | W4: 判定(余裕)
A5: D1 | B5: 46326 | C5: 0.47916667 | D5: 0.70833333 | E5: 50 | F5: =ROUND((D5-C5)*1440,0)-E5 -> 280 | G5: =SUMIFS(シーン見積!$G$4:$G$25,シーン見積!$C$4:$C$25,A5) -> 200 | H5: =SUMIFS(移動!$G$16:$G$32,移動!$A$16:$A$32,A5) -> 20 | I5: =F5-G5-H5 -> 60 | J5: 1 | K5: =SUMIFS(シーン見積!$Z$4:$Z$25,シーン見積!$C$4:$C$25,A5)+SUMIFS(移動!$D$16:$D$32,移動!$A$16:$A$32,A5)+J5*係数!$B$14 -> 108 | L5: =SUMIFS(シーン見積!$AD$4:$AD$25,シーン見積!$C$4:$C$25,A5)+SUMIFS(移動!$E$16:$E$32,移動!$A$16:$A$32,A5)+J5*係数!$C$14 -> 187 | M5: =SUMIFS(シーン見積!$AH$4:$AH$25,シーン見積!$C$4:$C$25,A5)+SUMIFS(移動!$F$16:$F$32,移動!$A$16:$A$32,A5)+J5*係数!$D$14 -> 280 | N5: =F5-K5 -> 172 | O5: =F5-L5 -> 93 | P5: =F5-M5 -> 0 | Q5: =IF(I5>0,MAX(0,L5-G5-H5)/I5,"予備なし") -> 0 | R5: =IF(I5>0,MAX(0,M5-G5-H5)/I5,"予備なし") -> 1 | S5: =C5+(E5+K5)/1440 -> 0.58888889 | T5: =C5+(E5+L5)/1440 -> 0.64375 | U5: =C5+(E5+M5)/1440 -> 0.70833333 | V5: =IF(T5<=D5+1/2880,"収まる",IF(S5<=D5+1/2880,"条件付き","超過")) -> 収まる | W5: =IF(U5<=D5+1/2880,"収まる","超過") -> 収まる
A6: D2a | B6: 46327 | C6: 0.4375 | D6: 0.63541667 | E6: 50 | F6: =ROUND((D6-C6)*1440,0)-E6 -> 235 | G6: =SUMIFS(シーン見積!$G$4:$G$25,シーン見積!$C$4:$C$25,A6) -> 185 | H6: =SUMIFS(移動!$G$16:$G$32,移動!$A$16:$A$32,A6) -> 10 | I6: =F6-G6-H6 -> 40 | J6: 3 | K6: =SUMIFS(シーン見積!$Z$4:$Z$25,シーン見積!$C$4:$C$25,A6)+SUMIFS(移動!$D$16:$D$32,移動!$A$16:$A$32,A6)+J6*係数!$B$14 -> 177 | L6: =SUMIFS(シーン見積!$AD$4:$AD$25,シーン見積!$C$4:$C$25,A6)+SUMIFS(移動!$E$16:$E$32,移動!$A$16:$A$32,A6)+J6*係数!$C$14 -> 305 | M6: =SUMIFS(シーン見積!$AH$4:$AH$25,シーン見積!$C$4:$C$25,A6)+SUMIFS(移動!$F$16:$F$32,移動!$A$16:$A$32,A6)+J6*係数!$D$14 -> 455 | N6: =F6-K6 -> 58 | O6: =F6-L6 -> -70 | P6: =F6-M6 -> -220 | Q6: =IF(I6>0,MAX(0,L6-G6-H6)/I6,"予備なし") -> 2.75 | R6: =IF(I6>0,MAX(0,M6-G6-H6)/I6,"予備なし") -> 6.5 | S6: =C6+(E6+K6)/1440 -> 0.59513889 | T6: =C6+(E6+L6)/1440 -> 0.68402778 | U6: =C6+(E6+M6)/1440 -> 0.78819444 | V6: =IF(T6<=D6+1/2880,"収まる",IF(S6<=D6+1/2880,"条件付き","超過")) -> 条件付き | W6: =IF(U6<=D6+1/2880,"収まる","超過") -> 超過
A7: D2b | B7: 46327 | C7: 0.63541667 | D7: 0.70833333 | E7: 0 | F7: =ROUND((D7-C7)*1440,0)-E7 -> 105 | G7: =SUMIFS(シーン見積!$G$4:$G$25,シーン見積!$C$4:$C$25,A7) -> 75 | H7: =SUMIFS(移動!$G$16:$G$32,移動!$A$16:$A$32,A7) -> 0 | I7: =F7-G7-H7 -> 30 | J7: 0 | K7: =SUMIFS(シーン見積!$Z$4:$Z$25,シーン見積!$C$4:$C$25,A7)+SUMIFS(移動!$D$16:$D$32,移動!$A$16:$A$32,A7)+J7*係数!$B$14 -> 46 | L7: =SUMIFS(シーン見積!$AD$4:$AD$25,シーン見積!$C$4:$C$25,A7)+SUMIFS(移動!$E$16:$E$32,移動!$A$16:$A$32,A7)+J7*係数!$C$14 -> 79 | M7: =SUMIFS(シーン見積!$AH$4:$AH$25,シーン見積!$C$4:$C$25,A7)+SUMIFS(移動!$F$16:$F$32,移動!$A$16:$A$32,A7)+J7*係数!$D$14 -> 116 | N7: =F7-K7 -> 59 | O7: =F7-L7 -> 26 | P7: =F7-M7 -> -11 | Q7: =IF(I7>0,MAX(0,L7-G7-H7)/I7,"予備なし") -> 0.13333333 | R7: =IF(I7>0,MAX(0,M7-G7-H7)/I7,"予備なし") -> 1.3666667 | S7: =MAX(C7,S6)+(E7+K7)/1440 -> 0.66736111 | T7: =MAX(C7,T6)+(E7+L7)/1440 -> 0.73888889 | U7: =MAX(C7,U6)+(E7+M7)/1440 -> 0.86875 | V7: =IF(T7<=D7+1/2880,"収まる",IF(S7<=D7+1/2880,"条件付き","超過")) -> 条件付き | W7: =IF(U7<=D7+1/2880,"収まる","超過") -> 超過
A8: D3a | B8: 46329 | C8: 0.33333333 | D8: 0.63541667 | E8: 50 | F8: =ROUND((D8-C8)*1440,0)-E8 -> 385 | G8: =SUMIFS(シーン見積!$G$4:$G$25,シーン見積!$C$4:$C$25,A8) -> 300 | H8: =SUMIFS(移動!$G$16:$G$32,移動!$A$16:$A$32,A8) -> 10 | I8: =F8-G8-H8 -> 75 | J8: 4 | K8: =SUMIFS(シーン見積!$Z$4:$Z$25,シーン見積!$C$4:$C$25,A8)+SUMIFS(移動!$D$16:$D$32,移動!$A$16:$A$32,A8)+J8*係数!$B$14 -> 301 | L8: =SUMIFS(シーン見積!$AD$4:$AD$25,シーン見積!$C$4:$C$25,A8)+SUMIFS(移動!$E$16:$E$32,移動!$A$16:$A$32,A8)+J8*係数!$C$14 -> 512 | M8: =SUMIFS(シーン見積!$AH$4:$AH$25,シーン見積!$C$4:$C$25,A8)+SUMIFS(移動!$F$16:$F$32,移動!$A$16:$A$32,A8)+J8*係数!$D$14 -> 749 | N8: =F8-K8 -> 84 | O8: =F8-L8 -> -127 | P8: =F8-M8 -> -364 | Q8: =IF(I8>0,MAX(0,L8-G8-H8)/I8,"予備なし") -> 2.6933333 | R8: =IF(I8>0,MAX(0,M8-G8-H8)/I8,"予備なし") -> 5.8533333 | S8: =C8+(E8+K8)/1440 -> 0.57708333 | T8: =C8+(E8+L8)/1440 -> 0.72361111 | U8: =C8+(E8+M8)/1440 -> 0.88819444 | V8: =IF(T8<=D8+1/2880,"収まる",IF(S8<=D8+1/2880,"条件付き","超過")) -> 条件付き | W8: =IF(U8<=D8+1/2880,"収まる","超過") -> 超過
A9: D3b | B9: 46329 | C9: 0.63541667 | D9: =日没!C7+日没!C12/1440 -> 0.73055556 | E9: 0 | F9: =ROUND((D9-C9)*1440,0)-E9 -> 137 | G9: =SUMIFS(シーン見積!$G$4:$G$25,シーン見積!$C$4:$C$25,A9) -> 105 | H9: =SUMIFS(移動!$G$16:$G$32,移動!$A$16:$A$32,A9) -> 0 | I9: =F9-G9-H9 -> 32 | J9: 0 | K9: =SUMIFS(シーン見積!$Z$4:$Z$25,シーン見積!$C$4:$C$25,A9)+SUMIFS(移動!$D$16:$D$32,移動!$A$16:$A$32,A9)+J9*係数!$B$14 -> 54 | L9: =SUMIFS(シーン見積!$AD$4:$AD$25,シーン見積!$C$4:$C$25,A9)+SUMIFS(移動!$E$16:$E$32,移動!$A$16:$A$32,A9)+J9*係数!$C$14 -> 90 | M9: =SUMIFS(シーン見積!$AH$4:$AH$25,シーン見積!$C$4:$C$25,A9)+SUMIFS(移動!$F$16:$F$32,移動!$A$16:$A$32,A9)+J9*係数!$D$14 -> 132 | N9: =F9-K9 -> 83 | O9: =F9-L9 -> 47 | P9: =F9-M9 -> 5 | Q9: =IF(I9>0,MAX(0,L9-G9-H9)/I9,"予備なし") -> 0 | R9: =IF(I9>0,MAX(0,M9-G9-H9)/I9,"予備なし") -> 0.84375 | S9: =MAX(C9,S8)+(E9+K9)/1440 -> 0.67291667 | T9: =MAX(C9,T8)+(E9+L9)/1440 -> 0.78611111 | U9: =MAX(C9,U8)+(E9+M9)/1440 -> 0.97986111 | V9: =IF(T9<=D9+1/2880,"収まる",IF(S9<=D9+1/2880,"条件付き","超過")) -> 条件付き | W9: =IF(U9<=D9+1/2880,"収まる","超過") -> 超過
A10: D4a | B10: 46333 | C10: 0.45833333 | D10: 0.6875 | E10: 50 | F10: =ROUND((D10-C10)*1440,0)-E10 -> 280 | G10: =SUMIFS(シーン見積!$G$4:$G$25,シーン見積!$C$4:$C$25,A10) -> 210 | H10: =SUMIFS(移動!$G$16:$G$32,移動!$A$16:$A$32,A10) -> 70 | I10: =F10-G10-H10 -> 0 | J10: 3 | K10: =SUMIFS(シーン見積!$Z$4:$Z$25,シーン見積!$C$4:$C$25,A10)+SUMIFS(移動!$D$16:$D$32,移動!$A$16:$A$32,A10)+J10*係数!$B$14 -> 222 | L10: =SUMIFS(シーン見積!$AD$4:$AD$25,シーン見積!$C$4:$C$25,A10)+SUMIFS(移動!$E$16:$E$32,移動!$A$16:$A$32,A10)+J10*係数!$C$14 -> 392 | M10: =SUMIFS(シーン見積!$AH$4:$AH$25,シーン見積!$C$4:$C$25,A10)+SUMIFS(移動!$F$16:$F$32,移動!$A$16:$A$32,A10)+J10*係数!$D$14 -> 592 | N10: =F10-K10 -> 58 | O10: =F10-L10 -> -112 | P10: =F10-M10 -> -312 | Q10: =IF(I10>0,MAX(0,L10-G10-H10)/I10,"予備なし") -> 予備なし | R10: =IF(I10>0,MAX(0,M10-G10-H10)/I10,"予備なし") -> 予備なし | S10: =C10+(E10+K10)/1440 -> 0.64722222 | T10: =C10+(E10+L10)/1440 -> 0.76527778 | U10: =C10+(E10+M10)/1440 -> 0.90416667 | V10: =IF(T10<=D10+1/2880,"収まる",IF(S10<=D10+1/2880,"条件付き","超過")) -> 条件付き | W10: =IF(U10<=D10+1/2880,"収まる","超過") -> 超過
A11: D4b | B11: 46333 | C11: 0.6875 | D11: =日没!C4+10/1440 -> 0.72083333 | E11: 0 | F11: =ROUND((D11-C11)*1440,0)-E11 -> 48 | G11: =SUMIFS(シーン見積!$G$4:$G$25,シーン見積!$C$4:$C$25,A11) -> 45 | H11: =SUMIFS(移動!$G$16:$G$32,移動!$A$16:$A$32,A11) -> 0 | I11: =F11-G11-H11 -> 3 | J11: 0 | K11: =SUMIFS(シーン見積!$Z$4:$Z$25,シーン見積!$C$4:$C$25,A11)+SUMIFS(移動!$D$16:$D$32,移動!$A$16:$A$32,A11)+J11*係数!$B$14 -> 15 | L11: =SUMIFS(シーン見積!$AD$4:$AD$25,シーン見積!$C$4:$C$25,A11)+SUMIFS(移動!$E$16:$E$32,移動!$A$16:$A$32,A11)+J11*係数!$C$14 -> 25 | M11: =SUMIFS(シーン見積!$AH$4:$AH$25,シーン見積!$C$4:$C$25,A11)+SUMIFS(移動!$F$16:$F$32,移動!$A$16:$A$32,A11)+J11*係数!$D$14 -> 37 | N11: =F11-K11 -> 33 | O11: =F11-L11 -> 23 | P11: =F11-M11 -> 11 | Q11: =IF(I11>0,MAX(0,L11-G11-H11)/I11,"予備なし") -> 0 | R11: =IF(I11>0,MAX(0,M11-G11-H11)/I11,"予備なし") -> 0 | S11: =MAX(C11,S10)+(E11+K11)/1440 -> 0.69791667 | T11: =MAX(C11,T10)+(E11+L11)/1440 -> 0.78263889 | U11: =MAX(C11,U10)+(E11+M11)/1440 -> 0.92986111 | V11: =IF(T11<=D11+1/2880,"収まる",IF(S11<=D11+1/2880,"条件付き","超過")) -> 条件付き | W11: =IF(U11<=D11+1/2880,"収まる","超過") -> 超過
A14: 日ごとのまとめ（標準）
A15: 日 | B15: 日付 | C15: 使える時間(分) | D15: 必要:標準 | E15: 必要:余裕 | F15: 余白:標準 | G15: 余白:余裕 | H15: 終了予測:標準 | I15: 終了予測:余裕 | J15: 終了の上限
A16: DAY1 | B16: 46326 | C16: =SUMIFS($F$5:$F$11,$B$5:$B$11,B16) -> 280 | D16: =SUMIFS($L$5:$L$11,$B$5:$B$11,B16) -> 187 | E16: =SUMIFS($M$5:$M$11,$B$5:$B$11,B16) -> 280 | F16: =SUMIFS($O$5:$O$11,$B$5:$B$11,B16) -> 93 | G16: =SUMIFS($P$5:$P$11,$B$5:$B$11,B16) -> 0 | H16: =T5 -> 0.64375 | I16: =U5 -> 0.70833333 | J16: =D5 -> 0.70833333
A17: DAY2 | B17: 46327 | C17: =SUMIFS($F$5:$F$11,$B$5:$B$11,B17) -> 340 | D17: =SUMIFS($L$5:$L$11,$B$5:$B$11,B17) -> 384 | E17: =SUMIFS($M$5:$M$11,$B$5:$B$11,B17) -> 571 | F17: =SUMIFS($O$5:$O$11,$B$5:$B$11,B17) -> -44 | G17: =SUMIFS($P$5:$P$11,$B$5:$B$11,B17) -> -231 | H17: =T7 -> 0.73888889 | I17: =U7 -> 0.86875 | J17: =D7 -> 0.70833333
A18: DAY3 | B18: 46329 | C18: =SUMIFS($F$5:$F$11,$B$5:$B$11,B18) -> 522 | D18: =SUMIFS($L$5:$L$11,$B$5:$B$11,B18) -> 602 | E18: =SUMIFS($M$5:$M$11,$B$5:$B$11,B18) -> 881 | F18: =SUMIFS($O$5:$O$11,$B$5:$B$11,B18) -> -80 | G18: =SUMIFS($P$5:$P$11,$B$5:$B$11,B18) -> -359 | H18: =T9 -> 0.78611111 | I18: =U9 -> 0.97986111 | J18: =D9 -> 0.73055556
A19: DAY4 | B19: 46333 | C19: =SUMIFS($F$5:$F$11,$B$5:$B$11,B19) -> 328 | D19: =SUMIFS($L$5:$L$11,$B$5:$B$11,B19) -> 417 | E19: =SUMIFS($M$5:$M$11,$B$5:$B$11,B19) -> 629 | F19: =SUMIFS($O$5:$O$11,$B$5:$B$11,B19) -> -89 | G19: =SUMIFS($P$5:$P$11,$B$5:$B$11,B19) -> -301 | H19: =T11 -> 0.78263889 | I19: =U11 -> 0.92986111 | J19: =D11 -> 0.72083333

Sheet 子ども拘束
A1: 子役・エキストラの拘束時間（現行表どおりの場合）
A2: 解放＝最後の出番の終了＋片付け15分。実働＝拘束−昼食（待ち時間も拘束に含めて考えます）。
A4: 日付 | B4: 人 | C4: 集合 | D4: 最後の出番の終了 | E4: 解放 | F4: 拘束(分) | G4: 昼食(分) | H4: 実働(分) | I4: 出番の合計(分) | J4: 待ち(分) | K4: 目安(7時間) | L4: 提案の集合 | M4: 提案の解放 | N4: 提案の実働(分) | O4: メモ
A5: 46326 | B5: リョウ | C5: 0.41666667 | D5: 0.53472222 | E5: =D5+15/1440 -> 0.54513889 | F5: =ROUND((E5-C5)*1440,0) -> 185 | G5: 0 | H5: =F5-G5 -> 185 | I5: 70 | J5: =H5-I5 -> 115 | K5: =IF(H5>係数!$B$34,"超える",IF(H5>係数!$B$34-30,"ギリギリ","OK")) -> OK | L5: 0.41666667 | M5: =E5 -> 0.54513889 | N5: =ROUND((M5-L5)*1440,0)-IF(M5-L5>4/24,G5,0) -> 185 | O5: S3・S4のみ。昼前に解放できる
A6: 46326 | B6: チハル | C6: 0.41666667 | D6: 0.53472222 | E6: =D6+15/1440 -> 0.54513889 | F6: =ROUND((E6-C6)*1440,0) -> 185 | G6: 0 | H6: =F6-G6 -> 185 | I6: 70 | J6: =H6-I6 -> 115 | K6: =IF(H6>係数!$B$34,"超える",IF(H6>係数!$B$34-30,"ギリギリ","OK")) -> OK | L6: 0.41666667 | M6: =E6 -> 0.54513889 | N6: =ROUND((M6-L6)*1440,0)-IF(M6-L6>4/24,G6,0) -> 185 | O6: 同上
A7: 46326 | B7: ソウタ | C7: 0.41666667 | D7: 0.66666667 | E7: =D7+15/1440 -> 0.67708333 | F7: =ROUND((E7-C7)*1440,0) -> 375 | G7: 50 | H7: =F7-G7 -> 325 | I7: 90 | J7: =H7-I7 -> 235 | K7: =IF(H7>係数!$B$34,"超える",IF(H7>係数!$B$34-30,"ギリギリ","OK")) -> OK | L7: 0.54166667 | M7: =E7 -> 0.67708333 | N7: =ROUND((M7-L7)*1440,0)-IF(M7-L7>4/24,G7,0) -> 195 | O7: 出番はS13（14:30〜）だけ。10:00集合だと4時間半待ち
A8: 46326 | B8: エキストラ②（全体） | C8: 0.45833333 | D8: 0.70833333 | E8: =D8+15/1440 -> 0.71875 | F8: =ROUND((E8-C8)*1440,0) -> 375 | G8: 50 | H8: =F8-G8 -> 325 | I8: 125 | J8: =H8-I8 -> 200 | K8: =IF(H8>係数!$B$34,"超える",IF(H8>係数!$B$34-30,"ギリギリ","OK")) -> OK | L8: 0.45833333 | M8: 0.61111111 | N8: =ROUND((M8-L8)*1440,0)-IF(M8-L8>4/24,G8,0) -> 220 | O8: S16Aの後にざわめき別撮りをすれば14:40に解放できる
A9: 46326 | B9: 男子3人（②から） | C9: 0.45833333 | D9: 0.66666667 | E9: =D9+15/1440 -> 0.67708333 | F9: =ROUND((E9-C9)*1440,0) -> 315 | G9: 50 | H9: =F9-G9 -> 265 | I9: 200 | J9: =H9-I9 -> 65 | K9: =IF(H9>係数!$B$34,"超える",IF(H9>係数!$B$34-30,"ギリギリ","OK")) -> OK | L9: 0.45833333 | M9: =E9 -> 0.67708333 | N9: =ROUND((M9-L9)*1440,0)-IF(M9-L9>4/24,G9,0) -> 265 | O9: S13の台詞あり。S12の「男の子の声」もここで録れる
A10: 46327 | B10: リョウ | C10: 0.375 | D10: 0.6875 | E10: =D10+15/1440 -> 0.69791667 | F10: =ROUND((E10-C10)*1440,0) -> 465 | G10: 50 | H10: =F10-G10 -> 415 | I10: 240 | J10: =H10-I10 -> 175 | K10: =IF(H10>係数!$B$34,"超える",IF(H10>係数!$B$34-30,"ギリギリ","OK")) -> ギリギリ | L10: 0.375 | M10: =E10 -> 0.69791667 | N10: =ROUND((M10-L10)*1440,0)-IF(M10-L10>4/24,G10,0) -> 415
A11: 46327 | B11: ソウタ | C11: 0.375 | D11: 0.6875 | E11: =D11+15/1440 -> 0.69791667 | F11: =ROUND((E11-C11)*1440,0) -> 465 | G11: 50 | H11: =F11-G11 -> 415 | I11: 210 | J11: =H11-I11 -> 205 | K11: =IF(H11>係数!$B$34,"超える",IF(H11>係数!$B$34-30,"ギリギリ","OK")) -> ギリギリ | L11: 0.375 | M11: =E11 -> 0.69791667 | N11: =ROUND((M11-L11)*1440,0)-IF(M11-L11>4/24,G11,0) -> 415 | O11: S10は出番なし
A12: 46327 | B12: エキストラ① | C12: 0.41666667 | D12: 0.6875 | E12: =D12+15/1440 -> 0.69791667 | F12: =ROUND((E12-C12)*1440,0) -> 405 | G12: 50 | H12: =F12-G12 -> 355 | I12: 230 | J12: =H12-I12 -> 125 | K12: =IF(H12>係数!$B$34,"超える",IF(H12>係数!$B$34-30,"ギリギリ","OK")) -> OK | L12: 0.41666667 | M12: =E12 -> 0.69791667 | N12: =ROUND((M12-L12)*1440,0)-IF(M12-L12>4/24,G12,0) -> 355 | O12: S10は女子2〜3人だけ。他の子は14:15〜15:15に約1時間待ち
A13: 46329 | B13: リョウ | C13: 0.3125 | D13: 0.6875 | E13: =D13+15/1440 -> 0.69791667 | F13: =ROUND((E13-C13)*1440,0) -> 555 | G13: 50 | H13: =F13-G13 -> 505 | I13: 375 | J13: =H13-I13 -> 130 | K13: =IF(H13>係数!$B$34,"超える",IF(H13>係数!$B$34-30,"ギリギリ","OK")) -> 超える | L13: 0.3125 | M13: =E13 -> 0.69791667 | N13: =ROUND((M13-L13)*1440,0)-IF(M13-L13>4/24,G13,0) -> 505 | O13: 一番重い日。S19の後も夕方まで現場
A14: 46329 | B14: チハル | C14: 0.3125 | D14: 0.6875 | E14: =D14+15/1440 -> 0.69791667 | F14: =ROUND((E14-C14)*1440,0) -> 555 | G14: 50 | H14: =F14-G14 -> 505 | I14: 315 | J14: =H14-I14 -> 190 | K14: =IF(H14>係数!$B$34,"超える",IF(H14>係数!$B$34-30,"ギリギリ","OK")) -> 超える | L14: 0.3125 | M14: =E14 -> 0.69791667 | N14: =ROUND((M14-L14)*1440,0)-IF(M14-L14>4/24,G14,0) -> 505 | O14: 同上
A15: 46329 | B15: ソウタ | C15: 0.3125 | D15: 0.54166667 | E15: =D15+15/1440 -> 0.55208333 | F15: =ROUND((E15-C15)*1440,0) -> 345 | G15: 50 | H15: =F15-G15 -> 295 | I15: 180 | J15: =H15-I15 -> 115 | K15: =IF(H15>係数!$B$34,"超える",IF(H15>係数!$B$34-30,"ギリギリ","OK")) -> OK | L15: 0.3125 | M15: =E15 -> 0.55208333 | N15: =ROUND((M15-L15)*1440,0)-IF(M15-L15>4/24,G15,0) -> 295 | O15: S15・S16
A16: 46329 | B16: ミオ | C16: 0.3125 | D16: 0.46527778 | E16: =D16+15/1440 -> 0.47569444 | F16: =ROUND((E16-C16)*1440,0) -> 235 | G16: 0 | H16: =F16-G16 -> 235 | I16: 60 | J16: =H16-I16 -> 175 | K16: =IF(H16>係数!$B$34,"超える",IF(H16>係数!$B$34-30,"ギリギリ","OK")) -> OK | L16: 0.39583333 | M16: =E16 -> 0.47569444 | N16: =ROUND((M16-L16)*1440,0)-IF(M16-L16>4/24,G16,0) -> 115 | O16: 出番は10:10〜11:10だけ
A17: 46333 | B17: リョウ | C17: 0.4375 | D17: 0.71875 | E17: =D17+15/1440 -> 0.72916667 | F17: =ROUND((E17-C17)*1440,0) -> 420 | G17: 50 | H17: =F17-G17 -> 370 | I17: 255 | J17: =H17-I17 -> 115 | K17: =IF(H17>係数!$B$34,"超える",IF(H17>係数!$B$34-30,"ギリギリ","OK")) -> OK | L17: 0.4375 | M17: =E17 -> 0.72916667 | N17: =ROUND((M17-L17)*1440,0)-IF(M17-L17>4/24,G17,0) -> 370 | O17: 移動50分を含む
A18: 46333 | B18: チハル | C18: 0.4375 | D18: 0.71875 | E18: =D18+15/1440 -> 0.72916667 | F18: =ROUND((E18-C18)*1440,0) -> 420 | G18: 50 | H18: =F18-G18 -> 370 | I18: 255 | J18: =H18-I18 -> 115 | K18: =IF(H18>係数!$B$34,"超える",IF(H18>係数!$B$34-30,"ギリギリ","OK")) -> OK | L18: 0.4375 | M18: =E18 -> 0.72916667 | N18: =ROUND((M18-L18)*1440,0)-IF(M18-L18>4/24,G18,0) -> 370 | O18: 同上

Sheet 感度分析
A1: 感度分析：S11・S2・S5・S18の見積もりが外れた場合
A2: 標準の見積もりに倍率をかけたとき、そのブロックの余白（分）と終了予測がどう動くか。倍率は青字で変更できます。
F3: 倍率ごとのブロック余白（分） | K3: 倍率ごとのブロック終了予測
A4: S | B4: ブロック | C4: 標準(分) | D4: 現行の枠(分) | E4: ブロック余白:標準 | F4: 0.75 | G4: 1 | H4: 1.25 | I4: 1.5 | J4: 2 | K4: 0.75 | L4: 1 | M4: 1.25 | N4: 1.5 | O4: 2
A5: 11 | B5: =INDEX(シーン見積!$C$4:$C$25,MATCH(A5,シーン見積!$A$4:$A$25,0)) -> D3a | C5: =INDEX(シーン見積!$AD$4:$AD$25,MATCH(A5,シーン見積!$A$4:$A$25,0)) -> 94 | D5: =INDEX(シーン見積!$G$4:$G$25,MATCH(A5,シーン見積!$A$4:$A$25,0)) -> 60 | E5: =INDEX(日別!$O$5:$O$11,MATCH(B5,日別!$A$5:$A$11,0)) -> -127 | F5: =E5-(F$4-1)*C5 -> -103.5 | G5: =E5-(G$4-1)*C5 -> -127 | H5: =E5-(H$4-1)*C5 -> -150.5 | I5: =E5-(I$4-1)*C5 -> -174 | J5: =E5-(J$4-1)*C5 -> -221 | K5: =INDEX(日別!$T$5:$T$11,MATCH(B5,日別!$A$5:$A$11,0))+(K$4-1)*C5/1440 -> 0.70729167 | L5: =INDEX(日別!$T$5:$T$11,MATCH(B5,日別!$A$5:$A$11,0))+(L$4-1)*C5/1440 -> 0.72361111 | M5: =INDEX(日別!$T$5:$T$11,MATCH(B5,日別!$A$5:$A$11,0))+(M$4-1)*C5/1440 -> 0.73993056 | N5: =INDEX(日別!$T$5:$T$11,MATCH(B5,日別!$A$5:$A$11,0))+(N$4-1)*C5/1440 -> 0.75625 | O5: =INDEX(日別!$T$5:$T$11,MATCH(B5,日別!$A$5:$A$11,0))+(O$4-1)*C5/1440 -> 0.78888889
A6: 2 | B6: =INDEX(シーン見積!$C$4:$C$25,MATCH(A6,シーン見積!$A$4:$A$25,0)) -> D4a | C6: =INDEX(シーン見積!$AD$4:$AD$25,MATCH(A6,シーン見積!$A$4:$A$25,0)) -> 173 | D6: =INDEX(シーン見積!$G$4:$G$25,MATCH(A6,シーン見積!$A$4:$A$25,0)) -> 90 | E6: =INDEX(日別!$O$5:$O$11,MATCH(B6,日別!$A$5:$A$11,0)) -> -112 | F6: =E6-(F$4-1)*C6 -> -68.75 | G6: =E6-(G$4-1)*C6 -> -112 | H6: =E6-(H$4-1)*C6 -> -155.25 | I6: =E6-(I$4-1)*C6 -> -198.5 | J6: =E6-(J$4-1)*C6 -> -285 | K6: =INDEX(日別!$T$5:$T$11,MATCH(B6,日別!$A$5:$A$11,0))+(K$4-1)*C6/1440 -> 0.73524306 | L6: =INDEX(日別!$T$5:$T$11,MATCH(B6,日別!$A$5:$A$11,0))+(L$4-1)*C6/1440 -> 0.76527778 | M6: =INDEX(日別!$T$5:$T$11,MATCH(B6,日別!$A$5:$A$11,0))+(M$4-1)*C6/1440 -> 0.7953125 | N6: =INDEX(日別!$T$5:$T$11,MATCH(B6,日別!$A$5:$A$11,0))+(N$4-1)*C6/1440 -> 0.82534722 | O6: =INDEX(日別!$T$5:$T$11,MATCH(B6,日別!$A$5:$A$11,0))+(O$4-1)*C6/1440 -> 0.88541667
A7: 5 | B7: =INDEX(シーン見積!$C$4:$C$25,MATCH(A7,シーン見積!$A$4:$A$25,0)) -> D2a | C7: =INDEX(シーン見積!$AD$4:$AD$25,MATCH(A7,シーン見積!$A$4:$A$25,0)) -> 145 | D7: =INDEX(シーン見積!$G$4:$G$25,MATCH(A7,シーン見積!$A$4:$A$25,0)) -> 80 | E7: =INDEX(日別!$O$5:$O$11,MATCH(B7,日別!$A$5:$A$11,0)) -> -70 | F7: =E7-(F$4-1)*C7 -> -33.75 | G7: =E7-(G$4-1)*C7 -> -70 | H7: =E7-(H$4-1)*C7 -> -106.25 | I7: =E7-(I$4-1)*C7 -> -142.5 | J7: =E7-(J$4-1)*C7 -> -215 | K7: =INDEX(日別!$T$5:$T$11,MATCH(B7,日別!$A$5:$A$11,0))+(K$4-1)*C7/1440 -> 0.65885417 | L7: =INDEX(日別!$T$5:$T$11,MATCH(B7,日別!$A$5:$A$11,0))+(L$4-1)*C7/1440 -> 0.68402778 | M7: =INDEX(日別!$T$5:$T$11,MATCH(B7,日別!$A$5:$A$11,0))+(M$4-1)*C7/1440 -> 0.70920139 | N7: =INDEX(日別!$T$5:$T$11,MATCH(B7,日別!$A$5:$A$11,0))+(N$4-1)*C7/1440 -> 0.734375 | O7: =INDEX(日別!$T$5:$T$11,MATCH(B7,日別!$A$5:$A$11,0))+(O$4-1)*C7/1440 -> 0.78472222
A8: 18 | B8: =INDEX(シーン見積!$C$4:$C$25,MATCH(A8,シーン見積!$A$4:$A$25,0)) -> D2b | C8: =INDEX(シーン見積!$AD$4:$AD$25,MATCH(A8,シーン見積!$A$4:$A$25,0)) -> 69 | D8: =INDEX(シーン見積!$G$4:$G$25,MATCH(A8,シーン見積!$A$4:$A$25,0)) -> 75 | E8: =INDEX(日別!$O$5:$O$11,MATCH(B8,日別!$A$5:$A$11,0)) -> 26 | F8: =E8-(F$4-1)*C8 -> 43.25 | G8: =E8-(G$4-1)*C8 -> 26 | H8: =E8-(H$4-1)*C8 -> 8.75 | I8: =E8-(I$4-1)*C8 -> -8.5 | J8: =E8-(J$4-1)*C8 -> -43 | K8: =INDEX(日別!$T$5:$T$11,MATCH(B8,日別!$A$5:$A$11,0))+(K$4-1)*C8/1440 -> 0.72690972 | L8: =INDEX(日別!$T$5:$T$11,MATCH(B8,日別!$A$5:$A$11,0))+(L$4-1)*C8/1440 -> 0.73888889 | M8: =INDEX(日別!$T$5:$T$11,MATCH(B8,日別!$A$5:$A$11,0))+(M$4-1)*C8/1440 -> 0.75086806 | N8: =INDEX(日別!$T$5:$T$11,MATCH(B8,日別!$A$5:$A$11,0))+(N$4-1)*C8/1440 -> 0.76284722 | O8: =INDEX(日別!$T$5:$T$11,MATCH(B8,日別!$A$5:$A$11,0))+(O$4-1)*C8/1440 -> 0.78680556
A11: 読み方
A12: ・S5（D2a）とS2（D4a）は、×1.00でもブロックの余白がマイナス。×0.75（最短に近い）でもマイナスなので、枠を広げる手当てが必要です。
A13: ・S11（D3a）は、ブロックの最後（13:00〜）にあるので、S15の超過がそのまま流れ込みます。S11が×1.5になると、さらに約47分遅れて、S19の夕方の光（15:42〜17:12）に食い込みます。
A14: ・S18（D2b）は単体なら余白+26分。×1.25までは吸収できて、×1.5で約−9分。ただし実際の終了時刻は、前のD2aの超過で決まります。
A15: ・ブロック終了予測は、同じ日の他のシーンが標準どおりに進んだ場合の値です（前のブロックの遅れも含みます）。
A16: ・予備の消費が100%を超える＝予備を使い切ってもまだ足りない、という意味です。

Sheet 要確認
A1: 要確認の一覧（推測で埋めていない点）
A3: No | B3: 項目 | C3: なぜ必要か | D3: 誰に | E3: 期限の目安
A4: 1 | B4: 引き継ぎ資料（.md）の「0」「7 決定事項」「※」の数字 | C4: 今回は添付がなく読めていない。決定事項に反していないか照合が必要 | D4: 助監督（ご本人） | E4: すぐ
A5: 2 | B5: 構図マーカーの色（緑／ピンク／赤）の意味 | C5: ピンク・赤を「未確定」として扱った。違えば見積もりが変わる | D5: 監督 | E5: 10/25
A6: 3 | B6: S7（笹原の見回り）が撮影対象か | C6: 脚本に赤字で残っているが、現行表にない | D6: 監督 | E6: 10/25
A7: 4 | B7: S1・S21の場所：脚本は砂浜・通り、現行表は防波堤 | C7: 場所が違うと移動時間・画が変わる | D7: 監督・制作 | E7: 10/25
A8: 5 | B8: S19〜S22の構図数 | C8: 構図マーカーがない。仮に3・2・3・2で計算 | D8: 監督・撮影 | E8: 10/27
A9: 6 | B9: エキストラ②の人数 | C9: 10人と仮置き。係数が変わる | D9: 制作 | E9: 10/25
A10: 7 | B10: エキストラ①の人数（脚本は12名ほど） | C10: 12人で計算 | D10: 制作 | E10: 10/25
A11: 8 | B11: ロケ地の正確な日没時刻 | C11: 現行表の17:08（11/7）を使用。ロケ地の経度で数分変わる | D11: 制作 | E11: 10/29
